Workbook
Name SegmentaçãodeDados_ANO_FIM: #N/A
Name SegmentaçãodeDados_ANO_FIM11: #N/A
Name SegmentaçãodeDados_BASE_REGIONAL1: #N/A
Name SegmentaçãodeDados_LOCADORA1: #N/A
Name SegmentaçãodeDados_MÊS_FIM: #N/A
Name SegmentaçãodeDados_MÊS_FIM11: #N/A
Name SegmentaçãodeDados_MODELO1: #N/A
Name SegmentaçãodeDados_OBSERVAÇÕES1: #N/A

Sheet TAB VENCIMENTOS (2)
A1: FILTROS
A16: ANALITICO
B18: MÊS FIM | C18: UF | D18: VENCIMENTO | F18: BASE REGIONAL | G18: TOTAL | I18: VEICULO TIPO | J18: TOTAL
B19: JAN | D19: 4 | F19: NORTE | G19: 12 | I19: 4X4 | J19: 7
C20: PR | D20: 2 | F20: SUDESTE | G20: 10 | I20: LEVE | J20: 20
C21: RS | D21: 2 | F21: SUL | G21: 10 | I21: UTILITARIO | J21: 5
B22: FEV | D22: 4 | F22: TOTAL | G22: 32 | I22: TOTAL | J22: 32
C23: SC | D23: 1
C24: SP | D24: 3
B25: MAR | D25: 22
C26: AM | D26: 5
C27: AP | D27: 7 | F27: QTDE POR LOCADORA | G27: TOTAL
C28: PR | D28: 2 | F28: LOCALIZA | G28: 32
C29: RS | D29: 1 | F29: FIORINO | G29: 3 | I29: QTD POR CLIENTE | J29: TOTAL
C30: SC | D30: 2 | F30: MOBI | G30: 20 | I30: 0 | J30: 1
C31: SP | D31: 5 | F31: S10 | G31: 7 | I31: ADMINISTRATIVO | J31: 2
B32: ABR | D32: 2 | F32: SAVEIRO | G32: 2 | I32: I-SYSTEMS | J32: 4
C33: SP | D33: 2 | F33: TOTAL GERAL | G33: 32 | I33: TIM MOVEL | J33: 10
B34: TOTAL | D34: 32 | I34: VIVO | J34: 15
I35: TOTAL | J35: 32

Sheet Planilha1
A3: Soma de DIAS
A4: Rótulos de Linha | B4: UF | C4: Status | D4: Veículo | E4: JANEIRO | F4: FEVEREIRO | G4: MARÇO | H4: ABRIL | I4: Total Geral
A5: MOVIDA | B5: AM | C5: MANUTENÇÃO | D5: SIF8C86 | H5: 11 | I5: 11
D6: SIF8C90 | H6: 26 | I6: 26
D7: SIF8D26 | H7: 18 | I7: 18
D8: SYH8A01 | H8: 13 | I8: 13
C9: SINISTRO | D9: SIK0I05 | E9: 98 | I9: 98
B10: DF | C10: MANUTENÇÃO | D10: PVR3F21 | H10: 26 | I10: 26
D11: PXS0F24 | F11: 60 | I11: 60
B12: ES | C12: MANUTENÇÃO | D12: SIK6J32 | G12: 29 | I12: 29
C13: SINISTRO | D13: SIY3G52 | F13: 59 | I13: 59
B14: GO | C14: SINISTRO | D14: SYH7H48 | H14: 7 | I14: 7
B15: MA | C15: MANUTENÇÃO | D15: SIK4H97 | G15: 39 | I15: 39
D16: SIK4I03 | H16: 21 | I16: 21
C17: SINISTRO | D17: SIY3H10 | H17: 12 | I17: 12
D18: SIY3H17 | E18: 111 | I18: 111
D19: SYH7H50 | G19: 42 | I19: 42
B20: MG | C20: MANUTENÇÃO | D20: PXS0E97 | G20: 54 | I20: 54
D21: PXS0F41 | I21: 131
D22: SIF8D23 | F22: 81 | I22: 81
D23: SYH7G06 | F23: 81 | I23: 81
C24: SINISTRO | D24: PVR9E41 | I24: 137
B25: MS | C25: MANUTENÇÃO | D25: TLI8G26 | H25: 21 | I25: 21
B26: MT | C26: MANUTENÇÃO | D26: TBW5A79 | H26: 19 | I26: 19
B27: PA | C27: MANUTENÇÃO | D27: SIY3G03 | H27: 12 | I27: 12
D28: SIY3G57 | H28: 24 | I28: 24
D29: SIY3H34 | H29: 11 | I29: 11
D30: SIY3H71 | H30: 24 | I30: 24
D31: SIY3H72 | H31: 13 | I31: 13
D32: TEY8D65 | H32: 19 | I32: 19
C33: SINISTRO | D33: SIK6J81 | H33: 19 | I33: 19
D34: SIK6J96 | H34: 24 | I34: 24
D35: SIK6J97 | H35: 8 | I35: 8
D36: SIK7A65 | H36: 24 | I36: 24
D37: SIY3G01 | H37: 17 | I37: 17
D38: SYH7F74 | F38: 84 | I38: 84
B39: RS | C39: MANUTENÇÃO | D39: PXS0E83 | G39: 53 | I39: 53
B40: SC | C40: SINISTRO | D40: SYH7H84 | H40: 12 | I40: 12
B41: TO | C41: MANUTENÇÃO | D41: PVR9E33 | G41: 32 | I41: 32
D42: SIK6J18 | H42: 17 | I42: 17
...

Sheet DIRETOR
A1: CARGO | B1: DIRETOR
A3: ÚLTIMO CONDUTOR | B3: GASTO COMBUSTÍVEL FEVEREIRO | C3: Soma de GASTO COMBUSTÍVE MARÇO | D3: Soma de GASTO COMBUSTÍVE ABRIL
A4: FABIO GONZAGA | B4: 1273.64 | C4: 2184.84 | D4: 1557.53
A5: FABIO TADEU SOLA | B5: 604.79 | C5: 691.39 | D5: 333.4
A6: MATHEUS RODRIGUES MONTE | B6: 1740.56 | C6: 773.37 | D6: 1903.35
A7: MARCELO VALLADA | B7: 495.44 | C7: 758.54 | D7: 265.02
A8: Total Geral | B8: 4114.43 | C8: 4408.14 | D8: 4059.3

Sheet GERENTE
A1: CARGO | B1: (Vários itens)
A3: NOME | B3: GASTO COMBUSTÍVEL FEVEREIRO | C3: Soma de GASTO COMBUSTÍVE MARÇO | D3: Soma de GASTO COMBUSTÍVE ABRIL
A4: ANDERSON JULIAN ESTEVÃO | B4: 920.95 | C4: 996.58 | D4: 279.81
A5: CLEITON DOS SANTOS DIAS MAIA | B5: 1520 | C5: 1845.12 | D5: 980
A6: DAVYS ROGÉRIO DA SILVA SANTOS | B6: 518.15 | C6: 707.29 | D6: 294.14
A7: DIOGO HENRIQUE MARCONDES | B7: 842.59 | C7: 690.64 | D7: 664.9
A8: DOUGLAS DE MELO SANCHEZ | B8: 1073.33 | C8: 1151.94 | D8: 1057.27
A9: EDSON BRUNO MORELATO | B9: 617.23 | C9: 909.84 | D9: 481.98
A10: FABIO LASCOSCH COSTA 21381013805 | B10: 1198.49 | C10: 1389.3 | D10: 231.43
A11: FELIPE SILVA SANTOS | B11: 1198.59 | C11: 1402.4 | D11: 729.19
A12: FERNANDA DE BARROS VILLAS BOAS | B12: 0 | C12: 0 | D12: 0
A13: JANDER JUNIOR INACIO PRATES | B13: 864.68 | C13: 1216.82 | D13: 1470.61
A14: JEFFERSON ALVES DE SOUZA | B14: 893.14 | C14: 1572.6 | D14: 0
A15: JHONATHAN DE OLIVEIRA CHAGAS | B15: 1900.89 | C15: 2682.24 | D15: 1118.09
... A30: Total Geral | B30: 27687.35 | C30: 34925.52 | D30: 15961.11

Sheet COORDENADOR
A1: CARGO | B1: (Vários itens)
A3: ÚLTIMO CONDUTOR | B3: Soma de GASTO COMBUSTÍVEL FEVEREIRO | C3: Soma de GASTO COMBUSTÍVE MARÇO | D3: Soma de GASTO COMBUSTÍVE ABRIL2
A4: ADEILTON DE SOUZA NAZARETH | B4: 1040 | C4: 800 | D4: 266.01
A5: ADEMIR TOMAZ DE MELO | B5: 2042.12 | C5: 1880.33 | D5: 935.21
A6: ADLER DE SOUSA LIMA | B6: 2165.58 | C6: 1384.25 | D6: 0
A7: ALEXANDRE VERAS RE | B7: 560.03 | C7: 896.31 | D7: 603.99
A8: ANA CRISTINA FREIRE HOLANDA | B8: 400 | C8: 1372.39 | D8: 625.11
A9: ANDRE GRANDIZOLI PERIGO MOURA | B9: 951.88 | C9: 583.61 | D9: 0
A10: CESAR AUGUSTO MELO HOENISCH | B10: 1355.71 | C10: 943.39 | D10: 132.85
A11: CLEVERSON DAMIAO GOMES | B11: 100 | C11: 1075.55 | D11: 1188.52
A12: DANIEL VICENTE FERREIRA | B12: 947.25 | C12: 1545.29 | D12: 403.11
A13: DAVID VIEIRA MAIA | B13: 1355.41 | C13: 2143.14 | D13: 899.84
A14: DENIS MARTINS DE OLIVEIRA | B14: 734.9 | C14: 862.21 | D14: 517.25
A15: EDMUR LUIZ FERREIRA DA SILVA | B15: 2233.39 | C15: 1993.33 | D15: 465.62
... A42: Total Geral | B42: 33877.1 | C42: 45168.76 | D42: 23425.87

Sheet TAB DE VENCIMENTO
A1: FILTRO | B1: VENCIDO
A2: LOCADORA | B2: (Vários itens) | L2: FILTRO | M2: ATENÇÃO | Q2: FILTRO | R2: VENCIDO
A4: ANO FIM | B4: MÊS FIM | C4: UF | D4: PLACA | E4: MODELO | F4: QTD | L4: CONTRATOS EM ATENÇÃO -3 MESES P/ VENC. | M4: . | Q4: VENCIDOS - RESUMO | R4: .
A5: 2024 | B5: SET | C5: AM | D5: RNJ0D35 | E5: MOBI | F5: 1 | L5: ANO | M5: LOCALIZA | N5: TOTAL | Q5: ANO | R5: LOCALIZA | S5: COMPANHIA DAS AMERICAS | T5: TOTAL
B6: SET | C6: AM | D6: RNJ0D85 | E6: MOBI | F6: 1 | L6: 2026 | Q6: 2025 | S6: 9 | T6: 9
B7: SET | C7: AM | D7: RNJ0E06 | E7: MOBI | F7: 1 | L7: MAI | Q7: RS | S7: 2 | T7: 2
B8: SET | C8: AM | D8: RNJ0E08 | E8: MOBI | F8: 1 | L8: MG | M8: 6 | N8: 6 | Q8: PR | S8: 7 | T8: 7
B9: SET | C9: AM | D9: RNJ0E47 | E9: MOBI | F9: 1 | L9: ES | M9: 3 | N9: 3 | Q9: 2026 | R9: 32 | T9: 32
B10: OUT | C10: AM | D10: RMT3C06 | E10: FIORINO | F10: 1 | L10: JUL | Q10: SP | R10: 10 | T10: 10
A11: 2025 | B11: NOV | C11: PR | D11: EGT8D42 | E11: SAVEIRO | F11: 1 | L11: ES | M11: 1 | N11: 1 | Q11: SC | R11: 3 | T11: 3
B12: NOV | C12: PR | D12: EJE2E81 | E12: SAVEIRO | F12: 1 | L12: TOTAL | M12: 10 | N12: 10 | Q12: RS | R12: 3 | T12: 3
B13: NOV | C13: PR | D13: EKU7H03 | E13: SAVEIRO | F13: 1 | Q13: PR | R13: 4 | T13: 4
B14: NOV | C14: PR | D14: ENI6B54 | E14: SAVEIRO | F14: 1 | Q14: AP | R14: 7 | T14: 7
B15: NOV | C15: PR | D15: EUC7H36 | E15: SAVEIRO | F15: 1 | Q15: AM | R15: 5 | T15: 5
B16: NOV | C16: PR | D16: EXJ4J06 | E16: SAVEIRO | F16: 1 | Q16: TOTAL | R16: 32 | S16: 9 | T16: 41
B17: NOV | C17: PR | D17: FJX1H02 | E17: SAVEIRO | F17: 1
B18: NOV | C18: RS | D18: EXH5C42 | E18: SAVEIRO | F18: 1
B19: NOV | C19: RS | D19: FLC7G24 | E19: SAVEIRO | F19: 1
A20: 2026 | B20: JAN | C20: PR | D20: RVS2F62 | E20: S10 | F20: 1
B21: JAN | C21: PR | D21: RVS2F70 | E21: S10 | F21: 1
B22: JAN | C22: RS | D22: RVS2F59 | E22: S10 | F22: 1
B23: JAN | C23: RS | D23: RVS2F68 | E23: S10 | F23: 1
B24: FEV | C24: SC | D24: SHD9F12 | E24: MOBI | F24: 1
B25: FEV | C25: SP | D25: SHD9C87 | E25: MOBI | F25: 1
B26: FEV | C26: SP | D26: SHD9F08 | E26: MOBI | F26: 1
B27: FEV | C27: SP | D27: SHD9F19 | E27: MOBI | F27: 1
B28: MAR | C28: AM | D28: SHG1G58 | E28: MOBI | F28: 1
B29: MAR | C29: AM | D29: SHG3G78 | E29: MOBI | F29: 1
B30: MAR | C30: AM | D30: SHG3G79 | E30: MOBI | F30: 1
B31: MAR | C31: AM | D31: SHG3G86 | E31: MOBI | F31: 1
B32: MAR | C32: AM | D32: SHG5J66 | E32: MOBI | F32: 1
... B51: ABR | C51: SP | D51: SHO6A62 | E51: FIORINO | F51: 1
A52: TOTAL | F52: 47

Sheet RELATORIO BASE
A1: PLACA | B1: MODELO | C1: TIPO | D1: ANO DO VEÍCULO | E1: LOCADORA | F1: UF | G1: BASE REGIONAL | H1: ÚLTIMO CONDUTOR | I1: CARGO | J1: GASTO ALUGUEL | K1: GASTO COMBUSTÍVEL FEVEREIRO | L1: GASTO COMBUSTÍVE MARÇO | M1: GASTO COMBUSTÍVE ABRIL | N1: GASTO TAGY | O1: VENCIMENTO CONTRATO | P1: OBSERVAÇÕES | Q1: VALOR LOCADORA | R1: AUDI. VALOR | S1: MÊS FIM | T1: ANO FIM | U1: STATUS | V1: C.CUSTO | W1: IC | X1: CLIENTE | Y1: GASTO COMBUTIVEL NO TRIMESTRE (JAN,FEV,MAR) | Z1: MÉDIA MÊS POR TRIMESTRE
A2: UAS3B92 | B2: =VLOOKUP(A2,UNIC!C:W,2,0) -> SAVEIRO | C2: =VLOOKUP(A2,UNIC!C:W,3,0) -> UTILITARIO | D2: =VLOOKUP(A2,UNIC!C:W,5,0) -> 2026 | E2: =VLOOKUP(A2,UNIC!C:W,21,0) -> MOVIDA | F2: =VLOOKUP(Tabela1[[#This Row],[PLACA]],UNIC!C:R,15,0) -> RS | G2: =VLOOKUP(Tabela1[[#This Row],[PLACA]],UNIC!C:R,16,0) -> SUL | H2: =VLOOKUP(A2,UNIC!C:H,6,0) -> - | I2: =VLOOKUP(H2,UNIC!H:J,3,0) -> - | J2: =VLOOKUP(Tabela1[[#This Row],[PLACA]],UNIC!C:V,20,0) -> R$ 0,00 | K2: =IFERROR(VALUE(VLOOKUP(Tabela1[[#This Row],[PLACA]],[1]Planilha2!$A:$F,3,0)),"") | L2: =IFERROR(VALUE(VLOOKUP(Tabela1[[#This Row],[PLACA]],[1]Planilha2!$A:$F,4,0)),"") | M2: =IFERROR(VALUE(VLOOKUP(Tabela1[[#This Row],[PLACA]],[1]Planilha2!$A:$F,5,0)),"") | O2: =VLOOKUP(Tabela1[[#This Row],[PLACA]],BASE_LOCADORAS!B:F,5,0) -> #N/A | P2: =IF(Tabela1[[#This Row],[VENCIMENTO CONTRATO]]="SEM DADOS", "SEM DADOS", IF(ISERROR(DATEDIF(TODAY(),Tabela1[[#This Row],[VENCIMENTO CONTRATO]],"d")), "VENCIDO", IF(DATEDIF(TODAY(),Tabela1[[#This Row],[VENCIMENTO CONTRATO]],"d")>90, "EM DIAS", "ATENÇÃO" ) ) ) -> #N/A | Q2: =VLOOKUP(Tabela1[[#This Row],[PLACA]],BASE_LOCADORAS!B:G,6,0) -> #N/A | R2: =Tabela1[[#This Row],[VALOR LOCADORA]]=Tabela1[[#This Row],[GASTO ALUGUEL]] -> #N/A | S2: =UPPER(TEXT(Tabela1[[#This Row],[VENCIMENTO CONTRATO]],"MMM")) -> #N/A | T2: =IFERROR(YEAR(Tabela1[[#This Row],[VENCIMENTO CONTRATO]]),"-") -> - | U2: =VLOOKUP(Tabela1[[#This Row],[PLACA]],UNIC!C:T,18,0) -> PATIO | V2: =SUBSTITUTE(VLOOKUP(Tabela1[[#This Row],[PLACA]],UNIC!C:K,9,0),".", "") | W2: =VLOOKUP(Tabela1[[#This Row],[PLACA]],UNIC!C:M,10,0) -> 0 | X2: =VLOOKUP(Tabela1[[#This Row],[PLACA]],UNIC!C:M,11,0) -> 0 | Y2: =SUM(Tabela1[[#This Row],[GASTO COMBUSTÍVEL FEVEREIRO]:[GASTO COMBUSTÍVE ABRIL]]) -> 0 | Z2: =IFERROR(AVERAGE(Tabela1[[#This Row],[GASTO COMBUSTÍVE ABRIL]:[GASTO COMBUSTÍVE MARÇO]]),"-") -> -
A3: UAS3I79 | B3: =VLOOKUP(A3,UNIC!C:W,2,0) -> SAVEIRO | C3: =VLOOKUP(A3,UNIC!C:W,3,0) -> UTILITARIO | D3: =VLOOKUP(A3,UNIC!C:W,5,0) -> 2026 | E3: =VLOOKUP(A3,UNIC!C:W,21,0) -> MOVIDA | F3: =VLOOKUP(Tabela1[[#This Row],[PLACA]],UNIC!C:R,15,0) -> RS | G3: =VLOOKUP(Tabela1[[#This Row],[PLACA]],UNIC!C:R,16,0) -> SUL | H3: =VLOOKUP(A3,UNIC!C:H,6,0) -> - | I3: =VLOOKUP(H3,UNIC!H:J,3,0) -> - | J3: =VLOOKUP(Tabela1[[#This Row],[PLACA]],UNIC!C:V,20,0) -> R$ 0,00 | K3: =IFERROR(VALUE(VLOOKUP(Tabela1[[#This Row],[PLACA]],[1]Planilha2!$A:$F,3,0)),"") | L3: =IFERROR(VALUE(VLOOKUP(Tabela1[[#This Row],[PLACA]],[1]Planilha2!$A:$F,4,0)),"") | M3: =IFERROR(VALUE(VLOOKUP(Tabela1[[#This Row],[PLACA]],[1]Planilha2!$A:$F,5,0)),"") | O3: =VLOOKUP(Tabela1[[#This Row],[PLACA]],BASE_LOCADORAS!B:F,5,0) -> #N/A | P3: =IF(Tabela1[[#This Row],[VENCIMENTO CONTRATO]]="SEM DADOS", "SEM DADOS", IF(ISERROR(DATEDIF(TODAY(),Tabela1[[#This Row],[VENCIMENTO CONTRATO]],"d")), "VENCIDO", IF(DATEDIF(TODAY(),Tabela1[[#This Row],[VENCIMENTO CONTRATO]],"d")>90, "EM DIAS", "ATENÇÃO" ) ) ) -> #N/A | Q3: =VLOOKUP(Tabela1[[#This Row],[PLACA]],BASE_LOCADORAS!B:G,6,0) -> #N/A | R3: =Tabela1[[#This Row],[VALOR LOCADORA]]=Tabela1[[#This Row],[GASTO ALUGUEL]] -> #N/A | S3: =UPPER(TEXT(Tabela1[[#This Row],[VENCIMENTO CONTRATO]],"MMM")) -> #N/A | T3: =IFERROR(YEAR(Tabela1[[#This Row],[VENCIMENTO CONTRATO]]),"-") -> - | U3: =VLOOKUP(Tabela1[[#This Row],[PLACA]],UNIC!C:T,18,0) -> PATIO | V3: =SUBSTITUTE(VLOOKUP(Tabela1[[#This Row],[PLACA]],UNIC!C:K,9,0),".", "") | W3: =VLOOKUP(Tabela1[[#This Row],[PLACA]],UNIC!C:M,10,0) -> 0 | X3: =VLOOKUP(Tabela1[[#This Row],[PLACA]],UNIC!C:M,11,0) -> 0 | Y3: =SUM(Tabela1[[#This Row],[GASTO COMBUSTÍVEL FEVEREIRO]:[GASTO COMBUSTÍVE ABRIL]]) -> 0 | Z3: =IFERROR(AVERAGE(Tabela1[[#This Row],[GASTO COMBUSTÍVE ABRIL]:[GASTO COMBUSTÍVE MARÇO]]),"-") -> -
A4: UAS2J80 | B4: =VLOOKUP(A4,UNIC!C:W,2,0) -> SAVEIRO | C4: =VLOOKUP(A4,UNIC!C:W,3,0) -> UTILITARIO | D4: =VLOOKUP(A4,UNIC!C:W,5,0) -> 2026 | E4: =VLOOKUP(A4,UNIC!C:W,21,0) -> MOVIDA | F4: =VLOOKUP(Tabela1[[#This Row],[PLACA]],UNIC!C:R,15,0) -> RS | G4: =VLOOKUP(Tabela1[[#This Row],[PLACA]],UNIC!C:R,16,0) -> SUL | H4: =VLOOKUP(A4,UNIC!C:H,6,0) -> - | I4: =VLOOKUP(H4,UNIC!H:J,3,0) -> - | J4: =VLOOKUP(Tabela1[[#This Row],[PLACA]],UNIC!C:V,20,0) -> R$ 0,00 | K4: =IFERROR(VALUE(VLOOKUP(Tabela1[[#This Row],[PLACA]],[1]Planilha2!$A:$F,3,0)),"") | L4: =IFERROR(VALUE(VLOOKUP(Tabela1[[#This Row],[PLACA]],[1]Planilha2!$A:$F,4,0)),"") | M4: =IFERROR(VALUE(VLOOKUP(Tabela1[[#This Row],[PLACA]],[1]Planilha2!$A:$F,5,0)),"") | O4: =VLOOKUP(Tabela1[[#This Row],[PLACA]],BASE_LOCADORAS!B:F,5,0) -> #N/A | P4: =IF(Tabela1[[#This Row],[VENCIMENTO CONTRATO]]="SEM DADOS", "SEM DADOS", IF(ISERROR(DATEDIF(TODAY(),Tabela1[[#This Row],[VENCIMENTO CONTRATO]],"d")), "VENCIDO", IF(DATEDIF(TODAY(),Tabela1[[#This Row],[VENCIMENTO CONTRATO]],"d")>90, "EM DIAS", "ATENÇÃO" ) ) ) -> #N/A | Q4: =VLOOKUP(Tabela1[[#This Row],[PLACA]],BASE_LOCADORAS!B:G,6,0) -> #N/A | R4: =Tabela1[[#This Row],[VALOR LOCADORA]]=Tabela1[[#This Row],[GASTO ALUGUEL]] -> #N/A | S4: =UPPER(TEXT(Tabela1[[#This Row],[VENCIMENTO CONTRATO]],"MMM")) -> #N/A | T4: =IFERROR(YEAR(Tabela1[[#This Row],[VENCIMENTO CONTRATO]]),"-") -> - | U4: =VLOOKUP(Tabela1[[#This Row],[PLACA]],UNIC!C:T,18,0) -> PATIO | V4: =SUBSTITUTE(VLOOKUP(Tabela1[[#This Row],[PLACA]],UNIC!C:K,9,0),".", "") | W4: =VLOOKUP(Tabela1[[#This Row],[PLACA]],UNIC!C:M,10,0) -> 0 | X4: =VLOOKUP(Tabela1[[#This Row],[PLACA]],UNIC!C:M,11,0) -> 0 | Y4: =SUM(Tabela1[[#This Row],[GASTO COMBUSTÍVEL FEVEREIRO]:[GASTO COMBUSTÍVE ABRIL]]) -> 0 | Z4: =IFERROR(AVERAGE(Tabela1[[#This Row],[GASTO COMBUSTÍVE ABRIL]:[GASTO COMBUSTÍVE MARÇO]]),"-") -> -
A5: UAS3E08 | B5: =VLOOKUP(A5,UNIC!C:W,2,0) -> SAVEIRO | C5: =VLOOKUP(A5,UNIC!C:W,3,0) -> UTILITARIO | D5: =VLOOKUP(A5,UNIC!C:W,5,0) -> 2026 | E5: =VLOOKUP(A5,UNIC!C:W,21,0) -> MOVIDA | F5: =VLOOKUP(Tabela1[[#This Row],[PLACA]],UNIC!C:R,15,0) -> RS | G5: =VLOOKUP(Tabela1[[#This Row],[PLACA]],UNIC!C:R,16,0) -> SUL | H5: =VLOOKUP(A5,UNIC!C:H,6,0) -> - | I5: =VLOOKUP(H5,UNIC!H:J,3,0) -> - | J5: =VLOOKUP(Tabela1[[#This Row],[PLACA]],UNIC!C:V,20,0) -> R$ 0,00 | K5: =IFERROR(VALUE(VLOOKUP(Tabela1[[#This Row],[PLACA]],[1]Planilha2!$A:$F,3,0)),"") | L5: =IFERROR(VALUE(VLOOKUP(Tabela1[[#This Row],[PLACA]],[1]Planilha2!$A:$F,4,0)),"") | M5: =IFERROR(VALUE(VLOOKUP(Tabela1[[#This Row],[PLACA]],[1]Planilha2!$A:$F,5,0)),"") | O5: =VLOOKUP(Tabela1[[#This Row],[PLACA]],BASE_LOCADORAS!B:F,5,0) -> #N/A | P5: =IF(Tabela1[[#This Row],[VENCIMENTO CONTRATO]]="SEM DADOS", "SEM DADOS", IF(ISERROR(DATEDIF(TODAY(),Tabela1[[#This Row],[VENCIMENTO CONTRATO]],"d")), "VENCIDO", IF(DATEDIF(TODAY(),Tabela1[[#This Row],[VENCIMENTO CONTRATO]],"d")>90, "EM DIAS", "ATENÇÃO" ) ) ) -> #N/A | Q5: =VLOOKUP(Tabela1[[#This Row],[PLACA]],BASE_LOCADORAS!B:G,6,0) -> #N/A | R5: =Tabela1[[#This Row],[VALOR LOCADORA]]=Tabela1[[#This Row],[GASTO ALUGUEL]] -> #N/A | S5: =UPPER(TEXT(Tabela1[[#This Row],[VENCIMENTO CONTRATO]],"MMM")) -> #N/A | T5: =IFERROR(YEAR(Tabela1[[#This Row],[VENCIMENTO CONTRATO]]),"-") -> - | U5: =VLOOKUP(Tabela1[[#This Row],[PLACA]],UNIC!C:T,18,0) -> PATIO | V5: =SUBSTITUTE(VLOOKUP(Tabela1[[#This Row],[PLACA]],UNIC!C:K,9,0),".", "") | W5: =VLOOKUP(Tabela1[[#This Row],[PLACA]],UNIC!C:M,10,0) -> 0 | X5: =VLOOKUP(Tabela1[[#This Row],[PLACA]],UNIC!C:M,11,0) -> 0 | Y5: =SUM(Tabela1[[#This Row],[GASTO COMBUSTÍVEL FEVEREIRO]:[GASTO COMBUSTÍVE ABRIL]]) -> 0 | Z5: =IFERROR(AVERAGE(Tabela1[[#This Row],[GASTO COMBUSTÍVE ABRIL]:[GASTO COMBUSTÍVE MARÇO]]),"-") -> -
A6: UAS3G94 | B6: =VLOOKUP(A6,UNIC!C:W,2,0) -> SAVEIRO | C6: =VLOOKUP(A6,UNIC!C:W,3,0) -> UTILITARIO | D6: =VLOOKUP(A6,UNIC!C:W,5,0) -> 2026 | E6: =VLOOKUP(A6,UNIC!C:W,21,0) -> MOVIDA | F6: =VLOOKUP(Tabela1[[#This Row],[PLACA]],UNIC!C:R,15,0) -> RS | G6: =VLOOKUP(Tabela1[[#This Row],[PLACA]],UNIC!C:R,16,0) -> SUL | H6: =VLOOKUP(A6,UNIC!C:H,6,0) -> - | I6: =VLOOKUP(H6,UNIC!H:J,3,0) -> - | J6: =VLOOKUP(Tabela1[[#This Row],[PLACA]],UNIC!C:V,20,0) -> R$ 0,00 | K6: =IFERROR(VALUE(VLOOKUP(Tabela1[[#This Row],[PLACA]],[1]Planilha2!$A:$F,3,0)),"") | L6: =IFERROR(VALUE(VLOOKUP(Tabela1[[#This Row],[PLACA]],[1]Planilha2!$A:$F,4,0)),"") | M6: =IFERROR(VALUE(VLOOKUP(Tabela1[[#This Row],[PLACA]],[1]Planilha2!$A:$F,5,0)),"") | O6: =VLOOKUP(Tabela1[[#This Row],[PLACA]],BASE_LOCADORAS!B:F,5,0) -> #N/A | P6: =IF(Tabela1[[#This Row],[VENCIMENTO CONTRATO]]="SEM DADOS", "SEM DADOS", IF(ISERROR(DATEDIF(TODAY(),Tabela1[[#This Row],[VENCIMENTO CONTRATO]],"d")), "VENCIDO", IF(DATEDIF(TODAY(),Tabela1[[#This Row],[VENCIMENTO CONTRATO]],"d")>90, "EM DIAS", "ATENÇÃO" ) ) ) -> #N/A | Q6: =VLOOKUP(Tabela1[[#This Row],[PLACA]],BASE_LOCADORAS!B:G,6,0) -> #N/A | R6: =Tabela1[[#This Row],[VALOR LOCADORA]]=Tabela1[[#This Row],[GASTO ALUGUEL]] -> #N/A | S6: =UPPER(TEXT(Tabela1[[#This Row],[VENCIMENTO CONTRATO]],"MMM")) -> #N/A | T6: =IFERROR(YEAR(Tabela1[[#This Row],[VENCIMENTO CONTRATO]]),"-") -> - | U6: =VLOOKUP(Tabela1[[#This Row],[PLACA]],UNIC!C:T,18,0) -> PATIO | V6: =SUBSTITUTE(VLOOKUP(Tabela1[[#This Row],[PLACA]],UNIC!C:K,9,0),".", "") | W6: =VLOOKUP(Tabela1[[#This Row],[PLACA]],UNIC!C:M,10,0) -> 0 | X6: =VLOOKUP(Tabela1[[#This Row],[PLACA]],UNIC!C:M,11,0) -> 0 | Y6: =SUM(Tabela1[[#This Row],[GASTO COMBUSTÍVEL FEVEREIRO]:[GASTO COMBUSTÍVE ABRIL]]) -> 0 | Z6: =IFERROR(AVERAGE(Tabela1[[#This Row],[GASTO COMBUSTÍVE ABRIL]:[GASTO COMBUSTÍVE MARÇO]]),"-") -> -
A7: UAS0H69 | B7: =VLOOKUP(A7,UNIC!C:W,2,0) -> SAVEIRO | C7: =VLOOKUP(A7,UNIC!C:W,3,0) -> UTILITARIO | D7: =VLOOKUP(A7,UNIC!C:W,5,0) -> 2026 | E7: =VLOOKUP(A7,UNIC!C:W,21,0) -> MOVIDA | F7: =VLOOKUP(Tabela1[[#This Row],[PLACA]],UNIC!C:R,15,0) -> RS | G7: =VLOOKUP(Tabela1[[#This Row],[PLACA]],UNIC!C:R,16,0) -> SUL | H7: =VLOOKUP(A7,UNIC!C:H,6,0) -> - | I7: =VLOOKUP(H7,UNIC!H:J,3,0) -> - | J7: =VLOOKUP(Tabela1[[#This Row],[PLACA]],UNIC!C:V,20,0) -> R$ 0,00 | K7: =IFERROR(VALUE(VLOOKUP(Tabela1[[#This Row],[PLACA]],[1]Planilha2!$A:$F,3,0)),"") | L7: =IFERROR(VALUE(VLOOKUP(Tabela1[[#This Row],[PLACA]],[1]Planilha2!$A:$F,4,0)),"") | M7: =IFERROR(VALUE(VLOOKUP(Tabela1[[#This Row],[PLACA]],[1]Planilha2!$A:$F,5,0)),"") | O7: =VLOOKUP(Tabela1[[#This Row],[PLACA]],BASE_LOCADORAS!B:F,5,0) -> #N/A | P7: =IF(Tabela1[[#This Row],[VENCIMENTO CONTRATO]]="SEM DADOS", "SEM DADOS", IF(ISERROR(DATEDIF(TODAY(),Tabela1[[#This Row],[VENCIMENTO CONTRATO]],"d")), "VENCIDO", IF(DATEDIF(TODAY(),Tabela1[[#This Row],[VENCIMENTO CONTRATO]],"d")>90, "EM DIAS", "ATENÇÃO" ) ) ) -> #N/A | Q7: =VLOOKUP(Tabela1[[#This Row],[PLACA]],BASE_LOCADORAS!B:G,6,0) -> #N/A | R7: =Tabela1[[#This Row],[VALOR LOCADORA]]=Tabela1[[#This Row],[GASTO ALUGUEL]] -> #N/A | S7: =UPPER(TEXT(Tabela1[[#This Row],[VENCIMENTO CONTRATO]],"MMM")) -> #N/A | T7: =IFERROR(YEAR(Tabela1[[#This Row],[VENCIMENTO CONTRATO]]),"-") -> - | U7: =VLOOKUP(Tabela1[[#This Row],[PLACA]],UNIC!C:T,18,0) -> PATIO | V7: =SUBSTITUTE(VLOOKUP(Tabela1[[#This Row],[PLACA]],UNIC!C:K,9,0),".", "") | W7: =VLOOKUP(Tabela1[[#This Row],[PLACA]],UNIC!C:M,10,0) -> 0 | X7: =VLOOKUP(Tabela1[[#This Row],[PLACA]],UNIC!C:M,11,0) -> 0 | Y7: =SUM(Tabela1[[#This Row],[GASTO COMBUSTÍVEL FEVEREIRO]:[GASTO COMBUSTÍVE ABRIL]]) -> 0 | Z7: =IFERROR(AVERAGE(Tabela1[[#This Row],[GASTO COMBUSTÍVE ABRIL]:[GASTO COMBUSTÍVE MARÇO]]),"-") -> -
A8: UAS0H57 | B8: =VLOOKUP(A8,UNIC!C:W,2,0) -> SAVEIRO | C8: =VLOOKUP(A8,UNIC!C:W,3,0) -> UTILITARIO | D8: =VLOOKUP(A8,UNIC!C:W,5,0) -> 2026 | E8: =VLOOKUP(A8,UNIC!C:W,21,0) -> MOVIDA | F8: =VLOOKUP(Tabela1[[#This Row],[PLACA]],UNIC!C:R,15,0) -> RS | G8: =VLOOKUP(Tabela1[[#This Row],[PLACA]],UNIC!C:R,16,0) -> SUL | H8: =VLOOKUP(A8,UNIC!C:H,6,0) -> - | I8: =VLOOKUP(H8,UNIC!H:J,3,0) -> - | J8: =VLOOKUP(Tabela1[[#This Row],[PLACA]],UNIC!C:V,20,0) -> R$ 0,00 | K8: =IFERROR(VALUE(VLOOKUP(Tabela1[[#This Row],[PLACA]],[1]Planilha2!$A:$F,3,0)),"") | L8: =IFERROR(VALUE(VLOOKUP(Tabela1[[#This Row],[PLACA]],[1]Planilha2!$A:$F,4,0)),"") | M8: =IFERROR(VALUE(VLOOKUP(Tabela1[[#This Row],[PLACA]],[1]Planilha2!$A:$F,5,0)),"") | O8: =VLOOKUP(Tabela1[[#This Row],[PLACA]],BASE_LOCADORAS!B:F,5,0) -> #N/A | P8: =IF(Tabela1[[#This Row],[VENCIMENTO CONTRATO]]="SEM DADOS", "SEM DADOS", IF(ISERROR(DATEDIF(TODAY(),Tabela1[[#This Row],[VENCIMENTO CONTRATO]],"d")), "VENCIDO", IF(DATEDIF(TODAY(),Tabela1[[#This Row],[VENCIMENTO CONTRATO]],"d")>90, "EM DIAS", "ATENÇÃO" ) ) ) -> #N/A | Q8: =VLOOKUP(Tabela1[[#This Row],[PLACA]],BASE_LOCADORAS!B:G,6,0) -> #N/A | R8: =Tabela1[[#This Row],[VALOR LOCADORA]]=Tabela1[[#This Row],[GASTO ALUGUEL]] -> #N/A | S8: =UPPER(TEXT(Tabela1[[#This Row],[VENCIMENTO CONTRATO]],"MMM")) -> #N/A | T8: =IFERROR(YEAR(Tabela1[[#This Row],[VENCIMENTO CONTRATO]]),"-") -> - | U8: =VLOOKUP(Tabela1[[#This Row],[PLACA]],UNIC!C:T,18,0) -> PATIO | V8: =SUBSTITUTE(VLOOKUP(Tabela1[[#This Row],[PLACA]],UNIC!C:K,9,0),".", "") | W8: =VLOOKUP(Tabela1[[#This Row],[PLACA]],UNIC!C:M,10,0) -> 0 | X8: =VLOOKUP(Tabela1[[#This Row],[PLACA]],UNIC!C:M,11,0) -> 0 | Y8: =SUM(Tabela1[[#This Row],[GASTO COMBUSTÍVEL FEVEREIRO]:[GASTO COMBUSTÍVE ABRIL]]) -> 0 | Z8: =IFERROR(AVERAGE(Tabela1[[#This Row],[GASTO COMBUSTÍVE ABRIL]:[GASTO COMBUSTÍVE MARÇO]]),"-") -> -
A9: UAS0H48 | B9: =VLOOKUP(A9,UNIC!C:W,2,0) -> SAVEIRO | C9: =VLOOKUP(A9,UNIC!C:W,3,0) -> UTILITARIO | D9: =VLOOKUP(A9,UNIC!C:W,5,0) -> 2026 | E9: =VLOOKUP(A9,UNIC!C:W,21,0) -> MOVIDA | F9: =VLOOKUP(Tabela1[[#This Row],[PLACA]],UNIC!C:R,15,0) -> RS | G9: =VLOOKUP(Tabela1[[#This Row],[PLACA]],UNIC!C:R,16,0) -> SUL | H9: =VLOOKUP(A9,UNIC!C:H,6,0) -> - | I9: =VLOOKUP(H9,UNIC!H:J,3,0) -> - | J9: =VLOOKUP(Tabela1[[#This Row],[PLACA]],UNIC!C:V,20,0) -> R$ 0,00 | K9: =IFERROR(VALUE(VLOOKUP(Tabela1[[#This Row],[PLACA]],[1]Planilha2!$A:$F,3,0)),"") | L9: =IFERROR(VALUE(VLOOKUP(Tabela1[[#This Row],[PLACA]],[1]Planilha2!$A:$F,4,0)),"") | M9: =IFERROR(VALUE(VLOOKUP(Tabela1[[#This Row],[PLACA]],[1]Planilha2!$A:$F,5,0)),"") | O9: =VLOOKUP(Tabela1[[#This Row],[PLACA]],BASE_LOCADORAS!B:F,5,0) -> #N/A | P9: =IF(Tabela1[[#This Row],[VENCIMENTO CONTRATO]]="SEM DADOS", "SEM DADOS", IF(ISERROR(DATEDIF(TODAY(),Tabela1[[#This Row],[VENCIMENTO CONTRATO]],"d")), "VENCIDO", IF(DATEDIF(TODAY(),Tabela1[[#This Row],[VENCIMENTO CONTRATO]],"d")>90, "EM DIAS", "ATENÇÃO" ) ) ) -> #N/A | Q9: =VLOOKUP(Tabela1[[#This Row],[PLACA]],BASE_LOCADORAS!B:G,6,0) -> #N/A | R9: =Tabela1[[#This Row],[VALOR LOCADORA]]=Tabela1[[#This Row],[GASTO ALUGUEL]] -> #N/A | S9: =UPPER(TEXT(Tabela1[[#This Row],[VENCIMENTO CONTRATO]],"MMM")) -> #N/A | T9: =IFERROR(YEAR(Tabela1[[#This Row],[VENCIMENTO CONTRATO]]),"-") -> - | U9: =VLOOKUP(Tabela1[[#This Row],[PLACA]],UNIC!C:T,18,0) -> PATIO | V9: =SUBSTITUTE(VLOOKUP(Tabela1[[#This Row],[PLACA]],UNIC!C:K,9,0),".", "") | W9: =VLOOKUP(Tabela1[[#This Row],[PLACA]],UNIC!C:M,10,0) -> 0 | X9: =VLOOKUP(Tabela1[[#This Row],[PLACA]],UNIC!C:M,11,0) -> 0 | Y9: =SUM(Tabela1[[#This Row],[GASTO COMBUSTÍVEL FEVEREIRO]:[GASTO COMBUSTÍVE ABRIL]]) -> 0 | Z9: =IFERROR(AVERAGE(Tabela1[[#This Row],[GASTO COMBUSTÍVE ABRIL]:[GASTO COMBUSTÍVE MARÇO]]),"-") -> -
A10: UAS0H36 | B10: =VLOOKUP(A10,UNIC!C:W,2,0) -> SAVEIRO | C10: =VLOOKUP(A10,UNIC!C:W,3,0) -> UTILITARIO | D10: =VLOOKUP(A10,UNIC!C:W,5,0) -> 2026 | E10: =VLOOKUP(A10,UNIC!C:W,21,0) -> MOVIDA | F10: =VLOOKUP(Tabela1[[#This Row],[PLACA]],UNIC!C:R,15,0) -> RS | G10: =VLOOKUP(Tabela1[[#This Row],[PLACA]],UNIC!C:R,16,0) -> SUL | H10: =VLOOKUP(A10,UNIC!C:H,6,0) -> - | I10: =VLOOKUP(H10,UNIC!H:J,3,0) -> - | J10: =VLOOKUP(Tabela1[[#This Row],[PLACA]],UNIC!C:V,20,0) -> R$ 2.026,00 | K10: =IFERROR(VALUE(VLOOKUP(Tabela1[[#This Row],[PLACA]],[1]Planilha2!$A:$F,3,0)),"") | L10: =IFERROR(VALUE(VLOOKUP(Tabela1[[#This Row],[PLACA]],[1]Planilha2!$A:$F,4,0)),"") | M10: =IFERROR(VALUE(VLOOKUP(Tabela1[[#This Row],[PLACA]],[1]Planilha2!$A:$F,5,0)),"") | O10: =VLOOKUP(Tabela1[[#This Row],[PLACA]],BASE_LOCADORAS!B:F,5,0) -> #N/A | P10: =IF(Tabela1[[#This Row],[VENCIMENTO CONTRATO]]="SEM DADOS", "SEM DADOS", IF(ISERROR(DATEDIF(TODAY(),Tabela1[[#This Row],[VENCIMENTO CONTRATO]],"d")), "VENCIDO", IF(DATEDIF(TODAY(),Tabela1[[#This Row],[VENCIMENTO CONTRATO]],"d")>90, "EM DIAS", "ATENÇÃO" ) ) ) -> #N/A | Q10: =VLOOKUP(Tabela1[[#This Row],[PLACA]],BASE_LOCADORAS!B:G,6,0) -> #N/A | R10: =Tabela1[[#This Row],[VALOR LOCADORA]]=Tabela1[[#This Row],[GASTO ALUGUEL]] -> #N/A | S10: =UPPER(TEXT(Tabela1[[#This Row],[VENCIMENTO CONTRATO]],"MMM")) -> #N/A | T10: =IFERROR(YEAR(Tabela1[[#This Row],[VENCIMENTO CONTRATO]]),"-") -> - | U10: =VLOOKUP(Tabela1[[#This Row],[PLACA]],UNIC!C:T,18,0) -> PATIO | V10: =SUBSTITUTE(VLOOKUP(Tabela1[[#This Row],[PLACA]],UNIC!C:K,9,0),".", "") | W10: =VLOOKUP(Tabela1[[#This Row],[PLACA]],UNIC!C:M,10,0) -> 0 | X10: =VLOOKUP(Tabela1[[#This Row],[PLACA]],UNIC!C:M,11,0) -> 0 | Y10: =SUM(Tabela1[[#This Row],[GASTO COMBUSTÍVEL FEVEREIRO]:[GASTO COMBUSTÍVE ABRIL]]) -> 0 | Z10: =IFERROR(AVERAGE(Tabela1[[#This Row],[GASTO COMBUSTÍVE ABRIL]:[GASTO COMBUSTÍVE MARÇO]]),"-") -> -
A11: UAS0H21 | B11: =VLOOKUP(A11,UNIC!C:W,2,0) -> SAVEIRO | C11: =VLOOKUP(A11,UNIC!C:W,3,0) -> UTILITARIO | D11: =VLOOKUP(A11,UNIC!C:W,5,0) -> 2026 | E11: =VLOOKUP(A11,UNIC!C:W,21,0) -> MOVIDA | F11: =VLOOKUP(Tabela1[[#This Row],[PLACA]],UNIC!C:R,15,0) -> RS | G11: =VLOOKUP(Tabela1[[#This Row],[PLACA]],UNIC!C:R,16,0) -> SUL | H11: =VLOOKUP(A11,UNIC!C:H,6,0) -> - | I11: =VLOOKUP(H11,UNIC!H:J,3,0) -> - | J11: =VLOOKUP(Tabela1[[#This Row],[PLACA]],UNIC!C:V,20,0) -> R$ 0,00 | K11: =IFERROR(VALUE(VLOOKUP(Tabela1[[#This Row],[PLACA]],[1]Planilha2!$A:$F,3,0)),"") | L11: =IFERROR(VALUE(VLOOKUP(Tabela1[[#This Row],[PLACA]],[1]Planilha2!$A:$F,4,0)),"") | M11: =IFERROR(VALUE(VLOOKUP(Tabela1[[#This Row],[PLACA]],[1]Planilha2!$A:$F,5,0)),"") | O11: =VLOOKUP(Tabela1[[#This Row],[PLACA]],BASE_LOCADORAS!B:F,5,0) -> #N/A | P11: =IF(Tabela1[[#This Row],[VENCIMENTO CONTRATO]]="SEM DADOS", "SEM DADOS", IF(ISERROR(DATEDIF(TODAY(),Tabela1[[#This Row],[VENCIMENTO CONTRATO]],"d")), "VENCIDO", IF(DATEDIF(TODAY(),Tabela1[[#This Row],[VENCIMENTO CONTRATO]],"d")>90, "EM DIAS", "ATENÇÃO" ) ) ) -> #N/A | Q11: =VLOOKUP(Tabela1[[#This Row],[PLACA]],BASE_LOCADORAS!B:G,6,0) -> #N/A | R11: =Tabela1[[#This Row],[VALOR LOCADORA]]=Tabela1[[#This Row],[GASTO ALUGUEL]] -> #N/A | S11: =UPPER(TEXT(Tabela1[[#This Row],[VENCIMENTO CONTRATO]],"MMM")) -> #N/A | T11: =IFERROR(YEAR(Tabela1[[#This Row],[VENCIMENTO CONTRATO]]),"-") -> - | U11: =VLOOKUP(Tabela1[[#This Row],[PLACA]],UNIC!C:T,18,0) -> PATIO | V11: =SUBSTITUTE(VLOOKUP(Tabela1[[#This Row],[PLACA]],UNIC!C:K,9,0),".", "") | W11: =VLOOKUP(Tabela1[[#This Row],[PLACA]],UNIC!C:M,10,0) -> 0 | X11: =VLOOKUP(Tabela1[[#This Row],[PLACA]],UNIC!C:M,11,0) -> 0 | Y11: =SUM(Tabela1[[#This Row],[GASTO COMBUSTÍVEL FEVEREIRO]:[GASTO COMBUSTÍVE ABRIL]]) -> 0 | Z11: =IFERROR(AVERAGE(Tabela1[[#This Row],[GASTO COMBUSTÍVE ABRIL]:[GASTO COMBUSTÍVE MARÇO]]),"-") -> -
A12: UAS0G99 | B12: =VLOOKUP(A12,UNIC!C:W,2,0) -> SAVEIRO | C12: =VLOOKUP(A12,UNIC!C:W,3,0) -> UTILITARIO | D12: =VLOOKUP(A12,UNIC!C:W,5,0) -> 2026 | E12: =VLOOKUP(A12,UNIC!C:W,21,0) -> MOVIDA | F12: =VLOOKUP(Tabela1[[#This Row],[PLACA]],UNIC!C:R,15,0) -> RS | G12: =VLOOKUP(Tabela1[[#This Row],[PLACA]],UNIC!C:R,16,0) -> SUL | H12: =VLOOKUP(A12,UNIC!C:H,6,0) -> - | I12: =VLOOKUP(H12,UNIC!H:J,3,0) -> - | J12: =VLOOKUP(Tabela1[[#This Row],[PLACA]],UNIC!C:V,20,0) -> R$ 0,00 | K12: =IFERROR(VALUE(VLOOKUP(Tabela1[[#This Row],[PLACA]],[1]Planilha2!$A:$F,3,0)),"") | L12: =IFERROR(VALUE(VLOOKUP(Tabela1[[#This Row],[PLACA]],[1]Planilha2!$A:$F,4,0)),"") | M12: =IFERROR(VALUE(VLOOKUP(Tabela1[[#This Row],[PLACA]],[1]Planilha2!$A:$F,5,0)),"") | O12: =VLOOKUP(Tabela1[[#This Row],[PLACA]],BASE_LOCADORAS!B:F,5,0) -> #N/A | P12: =IF(Tabela1[[#This Row],[VENCIMENTO CONTRATO]]="SEM DADOS", "SEM DADOS", IF(ISERROR(DATEDIF(TODAY(),Tabela1[[#This Row],[VENCIMENTO CONTRATO]],"d")), "VENCIDO", IF(DATEDIF(TODAY(),Tabela1[[#This Row],[VENCIMENTO CONTRATO]],"d")>90, "EM DIAS", "ATENÇÃO" ) ) ) -> #N/A | Q12: =VLOOKUP(Tabela1[[#This Row],[PLACA]],BASE_LOCADORAS!B:G,6,0) -> #N/A | R12: =Tabela1[[#This Row],[VALOR LOCADORA]]=Tabela1[[#This Row],[GASTO ALUGUEL]] -> #N/A | S12: =UPPER(TEXT(Tabela1[[#This Row],[VENCIMENTO CONTRATO]],"MMM")) -> #N/A | T12: =IFERROR(YEAR(Tabela1[[#This Row],[VENCIMENTO CONTRATO]]),"-") -> - | U12: =VLOOKUP(Tabela1[[#This Row],[PLACA]],UNIC!C:T,18,0) -> PATIO | V12: =SUBSTITUTE(VLOOKUP(Tabela1[[#This Row],[PLACA]],UNIC!C:K,9,0),".", "") | W12: =VLOOKUP(Tabela1[[#This Row],[PLACA]],UNIC!C:M,10,0) -> 0 | X12: =VLOOKUP(Tabela1[[#This Row],[PLACA]],UNIC!C:M,11,0) -> 0 | Y12: =SUM(Tabela1[[#This Row],[GASTO COMBUSTÍVEL FEVEREIRO]:[GASTO COMBUSTÍVE ABRIL]]) -> 0 | Z12: =IFERROR(AVERAGE(Tabela1[[#This Row],[GASTO COMBUSTÍVE ABRIL]:[GASTO COMBUSTÍVE MARÇO]]),"-") -> -
A13: UAS0G93 | B13: =VLOOKUP(A13,UNIC!C:W,2,0) -> SAVEIRO | C13: =VLOOKUP(A13,UNIC!C:W,3,0) -> UTILITARIO | D13: =VLOOKUP(A13,UNIC!C:W,5,0) -> 2026 | E13: =VLOOKUP(A13,UNIC!C:W,21,0) -> MOVIDA | F13: =VLOOKUP(Tabela1[[#This Row],[PLACA]],UNIC!C:R,15,0) -> RS | G13: =VLOOKUP(Tabela1[[#This Row],[PLACA]],UNIC!C:R,16,0) -> SUL | H13: =VLOOKUP(A13,UNIC!C:H,6,0) -> - | I13: =VLOOKUP(H13,UNIC!H:J,3,0) -> - | J13: =VLOOKUP(Tabela1[[#This Row],[PLACA]],UNIC!C:V,20,0) -> R$ 0,00 | K13: =IFERROR(VALUE(VLOOKUP(Tabela1[[#This Row],[PLACA]],[1]Planilha2!$A:$F,3,0)),"") | L13: =IFERROR(VALUE(VLOOKUP(Tabela1[[#This Row],[PLACA]],[1]Planilha2!$A:$F,4,0)),"") | M13: =IFERROR(VALUE(VLOOKUP(Tabela1[[#This Row],[PLACA]],[1]Planilha2!$A:$F,5,0)),"") | O13: =VLOOKUP(Tabela1[[#This Row],[PLACA]],BASE_LOCADORAS!B:F,5,0) -> #N/A | P13: =IF(Tabela1[[#This Row],[VENCIMENTO CONTRATO]]="SEM DADOS", "SEM DADOS", IF(ISERROR(DATEDIF(TODAY(),Tabela1[[#This Row],[VENCIMENTO CONTRATO]],"d")), "VENCIDO", IF(DATEDIF(TODAY(),Tabela1[[#This Row],[VENCIMENTO CONTRATO]],"d")>90, "EM DIAS", "ATENÇÃO" ) ) ) -> #N/A | Q13: =VLOOKUP(Tabela1[[#This Row],[PLACA]],BASE_LOCADORAS!B:G,6,0) -> #N/A | R13: =Tabela1[[#This Row],[VALOR LOCADORA]]=Tabela1[[#This Row],[GASTO ALUGUEL]] -> #N/A | S13: =UPPER(TEXT(Tabela1[[#This Row],[VENCIMENTO CONTRATO]],"MMM")) -> #N/A | T13: =IFERROR(YEAR(Tabela1[[#This Row],[VENCIMENTO CONTRATO]]),"-") -> - | U13: =VLOOKUP(Tabela1[[#This Row],[PLACA]],UNIC!C:T,18,0) -> PATIO | V13: =SUBSTITUTE(VLOOKUP(Tabela1[[#This Row],[PLACA]],UNIC!C:K,9,0),".", "") | W13: =VLOOKUP(Tabela1[[#This Row],[PLACA]],UNIC!C:M,10,0) -> 0 | X13: =VLOOKUP(Tabela1[[#This Row],[PLACA]],UNIC!C:M,11,0) -> 0 | Y13: =SUM(Tabela1[[#This Row],[GASTO COMBUSTÍVEL FEVEREIRO]:[GASTO COMBUSTÍVE ABRIL]]) -> 0 | Z13: =IFERROR(AVERAGE(Tabela1[[#This Row],[GASTO COMBUSTÍVE ABRIL]:[GASTO COMBUSTÍVE MARÇO]]),"-") -> -
... A137: CUE8J13 | B137: =VLOOKUP(A137,UNIC!C:W,2,0) -> SAVEIRO | C137: =VLOOKUP(A137,UNIC!C:W,3,0) -> UTILITARIO | D137: =VLOOKUP(A137,UNIC!C:W,5,0) -> 2026 | E137: =VLOOKUP(A137,UNIC!C:W,21,0) -> MOVIDA | F137: =VLOOKUP(Tabela1[[#This Row],[PLACA]],UNIC!C:R,15,0) -> GO | G137: =VLOOKUP(Tabela1[[#This Row],[PLACA]],UNIC!C:R,16,0) -> CENTRO OESTE | H137: =VLOOKUP(A137,UNIC!C:H,6,0) -> WAGNER TELLES DA SILVA | I137: =VLOOKUP(H137,UNIC!H:J,3,0) -> TECNICO DE MANUTENCAO PI I | J137: =VLOOKUP(Tabela1[[#This Row],[PLACA]],UNIC!C:V,20,0) -> R$ 1,00 | K137: =IFERROR(VALUE(VLOOKUP(Tabela1[[#This Row],[PLACA]],[1]Planilha2!$A:$F,3,0)),"") -> 0 | L137: =IFERROR(VALUE(VLOOKUP(Tabela1[[#This Row],[PLACA]],[1]Planilha2!$A:$F,4,0)),"") -> 0 | M137: =IFERROR(VALUE(VLOOKUP(Tabela1[[#This Row],[PLACA]],[1]Planilha2!$A:$F,5,0)),"") -> 1388.82 | O137: =VLOOKUP(Tabela1[[#This Row],[PLACA]],BASE_LOCADORAS!B:F,5,0) -> #N/A | P137: =IF(Tabela1[[#This Row],[VENCIMENTO CONTRATO]]="SEM DADOS", "SEM DADOS", IF(ISERROR(DATEDIF(TODAY(),Tabela1[[#This Row],[VENCIMENTO CONTRATO]],"d")), "VENCIDO", IF(DATEDIF(TODAY(),Tabela1[[#This Row],[VENCIMENTO CONTRATO]],"d")>90, "EM DIAS", "ATENÇÃO" ) ) ) -> #N/A | Q137: =VLOOKUP(Tabela1[[#This Row],[PLACA]],BASE_LOCADORAS!B:G,6,0) -> #N/A | R137: =Tabela1[[#This Row],[VALOR LOCADORA]]=Tabela1[[#This Row],[GASTO ALUGUEL]] -> #N/A | S137: =UPPER(TEXT(Tabela1[[#This Row],[VENCIMENTO CONTRATO]],"MMM")) -> #N/A | T137: =IFERROR(YEAR(Tabela1[[#This Row],[VENCIMENTO CONTRATO]]),"-") -> - | U137: =VLOOKUP(Tabela1[[#This Row],[PLACA]],UNIC!C:T,18,0) -> ATIVO | V137: =SUBSTITUTE(VLOOKUP(Tabela1[[#This Row],[PLACA]],UNIC!C:K,9,0),".", "") -> 12081 | W137: =VLOOKUP(Tabela1[[#This Row],[PLACA]],UNIC!C:M,10,0) -> 19019 | X137: =VLOOKUP(Tabela1[[#This Row],[PLACA]],UNIC!C:M,11,0) -> TIM MOVEL | Y137: =SUM(Tabela1[[#This Row],[GASTO COMBUSTÍVEL FEVEREIRO]:[GASTO COMBUSTÍVE ABRIL]]) -> 1388.82 | Z137: =IFERROR(AVERAGE(Tabela1[[#This Row],[GASTO COMBUSTÍVE ABRIL]:[GASTO COMBUSTÍVE MARÇO]]),"-") -> 694.41
A138: SGO5E22 | B138: =VLOOKUP(A138,UNIC!C:W,2,0) -> TRACKER | C138: =VLOOKUP(A138,UNIC!C:W,3,0) -> SUV | D138: =VLOOKUP(A138,UNIC!C:W,5,0) -> 2022 | E138: =VLOOKUP(A138,UNIC!C:W,21,0) -> PARTICULAR | F138: =VLOOKUP(Tabela1[[#This Row],[PLACA]],UNIC!C:R,15,0) -> DF | G138: =VLOOKUP(Tabela1[[#This Row],[PLACA]],UNIC!C:R,16,0) -> CENTRO OESTE | H138: CLEITON DOS SANTOS DIAS MAIA | I138: =VLOOKUP(H138,UNIC!H:J,3,0) -> GERENTE OPERACAO JR | J138: =VLOOKUP(Tabela1[[#This Row],[PLACA]],UNIC!C:V,20,0) -> R$ 2.000,00 | K138: =IFERROR(VALUE(VLOOKUP(Tabela1[[#This Row],[PLACA]],[1]Planilha2!$A:$F,3,0)),"") -> 0 | L138: =IFERROR(VALUE(VLOOKUP(Tabela1[[#This Row],[PLACA]],[1]Planilha2!$A:$F,4,0)),"") -> 845.12 | M138: =IFERROR(VALUE(VLOOKUP(Tabela1[[#This Row],[PLACA]],[1]Planilha2!$A:$F,5,0)),"") -> 980 | O138: =VLOOKUP(Tabela1[[#This Row],[PLACA]],BASE_LOCADORAS!B:F,5,0) -> #N/A | P138: =IF(Tabela1[[#This Row],[VENCIMENTO CONTRATO]]="SEM DADOS", "SEM DADOS", IF(ISERROR(DATEDIF(TODAY(),Tabela1[[#This Row],[VENCIMENTO CONTRATO]],"d")), "VENCIDO", IF(DATEDIF(TODAY(),Tabela1[[#This Row],[VENCIMENTO CONTRATO]],"d")>90, "EM DIAS", "ATENÇÃO" ) ) ) -> #N/A | Q138: =VLOOKUP(Tabela1[[#This Row],[PLACA]],BASE_LOCADORAS!B:G,6,0) -> #N/A | R138: =Tabela1[[#This Row],[VALOR LOCADORA]]=Tabela1[[#This Row],[GASTO ALUGUEL]] -> #N/A | S138: =UPPER(TEXT(Tabela1[[#This Row],[VENCIMENTO CONTRATO]],"MMM")) -> #N/A | T138: =IFERROR(YEAR(Tabela1[[#This Row],[VENCIMENTO CONTRATO]]),"-") -> - | U138: =VLOOKUP(Tabela1[[#This Row],[PLACA]],UNIC!C:T,18,0) -> PATIO | V138: =SUBSTITUTE(VLOOKUP(Tabela1[[#This Row],[PLACA]],UNIC!C:K,9,0),".", "") | W138: =VLOOKUP(Tabela1[[#This Row],[PLACA]],UNIC!C:M,10,0) -> 0 | X138: =VLOOKUP(Tabela1[[#This Row],[PLACA]],UNIC!C:M,11,0) -> 0 | Y138: =SUM(Tabela1[[#This Row],[GASTO COMBUSTÍVEL FEVEREIRO]:[GASTO COMBUSTÍVE ABRIL]]) -> 1825.12 | Z138: =IFERROR(AVERAGE(Tabela1[[#This Row],[GASTO COMBUSTÍVE ABRIL]:[GASTO COMBUSTÍVE MARÇO]]),"-") -> 912.56
A139: LMY9J53 | B139: =VLOOKUP(A139,UNIC!C:W,2,0) -> VW | C139: =VLOOKUP(A139,UNIC!C:W,3,0) -> LEVE | D139: =VLOOKUP(A139,UNIC!C:W,5,0) -> 2020 | E139: =VLOOKUP(A139,UNIC!C:W,21,0) -> PARTICULAR | F139: =VLOOKUP(Tabela1[[#This Row],[PLACA]],UNIC!C:R,15,0) -> ES | G139: =VLOOKUP(Tabela1[[#This Row],[PLACA]],UNIC!C:R,16,0) -> SUDESTE | H139: =VLOOKUP(A139,UNIC!C:H,6,0) -> - | I139: =VLOOKUP(H139,UNIC!H:J,3,0) -> - | J139: =VLOOKUP(Tabela1[[#This Row],[PLACA]],UNIC!C:V,20,0) -> R$ 2.000,00 | K139: =IFERROR(VALUE(VLOOKUP(Tabela1[[#This Row],[PLACA]],[1]Planilha2!$A:$F,3,0)),"") -> 0 | L139: =IFERROR(VALUE(VLOOKUP(Tabela1[[#This Row],[PLACA]],[1]Planilha2!$A:$F,4,0)),"") -> 789.59 | M139: =IFERROR(VALUE(VLOOKUP(Tabela1[[#This Row],[PLACA]],[1]Planilha2!$A:$F,5,0)),"") -> 715.6 | O139: =VLOOKUP(Tabela1[[#This Row],[PLACA]],BASE_LOCADORAS!B:F,5,0) -> #N/A | P139: =IF(Tabela1[[#This Row],[VENCIMENTO CONTRATO]]="SEM DADOS", "SEM DADOS", IF(ISERROR(DATEDIF(TODAY(),Tabela1[[#This Row],[VENCIMENTO CONTRATO]],"d")), "VENCIDO", IF(DATEDIF(TODAY(),Tabela1[[#This Row],[VENCIMENTO CONTRATO]],"d")>90, "EM DIAS", "ATENÇÃO" ) ) ) -> #N/A | Q139: =VLOOKUP(Tabela1[[#This Row],[PLACA]],BASE_LOCADORAS!B:G,6,0) -> #N/A | R139: =Tabela1[[#This Row],[VALOR LOCADORA]]=Tabela1[[#This Row],[GASTO ALUGUEL]] -> #N/A | S139: =UPPER(TEXT(Tabela1[[#This Row],[VENCIMENTO CONTRATO]],"MMM")) -> #N/A | T139: =IFERROR(YEAR(Tabela1[[#This Row],[VENCIMENTO CONTRATO]]),"-") -> - | U139: =VLOOKUP(Tabela1[[#This Row],[PLACA]],UNIC!C:T,18,0) -> PATIO | V139: =SUBSTITUTE(VLOOKUP(Tabela1[[#This Row],[PLACA]],UNIC!C:K,9,0),".", "") | W139: =VLOOKUP(Tabela1[[#This Row],[PLACA]],UNIC!C:M,10,0) -> 0 | X139: =VLOOKUP(Tabela1[[#This Row],[PLACA]],UNIC!C:M,11,0) -> 0 | Y139: =SUM(Tabela1[[#This Row],[GASTO COMBUSTÍVEL FEVEREIRO]:[GASTO COMBUSTÍVE ABRIL]]) -> 1505.19 | Z139: =IFERROR(AVERAGE(Tabela1[[#This Row],[GASTO COMBUSTÍVE ABRIL]:[GASTO COMBUSTÍVE MARÇO]]),"-") -> 752.595
A140: GER2786 | B140: =VLOOKUP(A140,UNIC!C:W,2,0) -> B4T 9000E | C140: =VLOOKUP(A140,UNIC!C:W,3,0) -> GERADOR | D140: =VLOOKUP(A140,UNIC!C:W,5,0) -> 2025 | E140: =VLOOKUP(A140,UNIC!C:W,21,0) -> EQUIPAMENTO | F140: =VLOOKUP(Tabela1[[#This Row],[PLACA]],UNIC!C:R,15,0) -> TO | G140: =VLOOKUP(Tabela1[[#This Row],[PLACA]],UNIC!C:R,16,0) -> NORTE | H140: =VLOOKUP(A140,UNIC!C:H,6,0) -> - | I140: =VLOOKUP(H140,UNIC!H:J,3,0) -> - | J140: =VLOOKUP(Tabela1[[#This Row],[PLACA]],UNIC!C:V,20,0) -> R$ 0,00 | K140: =IFERROR(VALUE(VLOOKUP(Tabela1[[#This Row],[PLACA]],[1]Planilha2!$A:$F,3,0)),"") -> 0 | L140: =IFERROR(VALUE(VLOOKUP(Tabela1[[#This Row],[PLACA]],[1]Planilha2!$A:$F,4,0)),"") -> 326.79 | M140: =IFERROR(VALUE(VLOOKUP(Tabela1[[#This Row],[PLACA]],[1]Planilha2!$A:$F,5,0)),"") -> 338.65 | O140: =VLOOKUP(Tabela1[[#This Row],[PLACA]],BASE_LOCADORAS!B:F,5,0) -> #N/A | P140: =IF(Tabela1[[#This Row],[VENCIMENTO CONTRATO]]="SEM DADOS", "SEM DADOS", IF(ISERROR(DATEDIF(TODAY(),Tabela1[[#This Row],[VENCIMENTO CONTRATO]],"d")), "VENCIDO", IF(DATEDIF(TODAY(),Tabela1[[#This Row],[VENCIMENTO CONTRATO]],"d")>90, "EM DIAS", "ATENÇÃO" ) ) ) -> #N/A | Q140: =VLOOKUP(Tabela1[[#This Row],[PLACA]],BASE_LOCADORAS!B:G,6,0) -> #N/A | R140: =Tabela1[[#This Row],[VALOR LOCADORA]]=Tabela1[[#This Row],[GASTO ALUGUEL]] -> #N/A | S140: =UPPER(TEXT(Tabela1[[#This Row],[VENCIMENTO CONTRATO]],"MMM")) -> #N/A | T140: =IFERROR(YEAR(Tabela1[[#This Row],[VENCIMENTO CONTRATO]]),"-") -> - | U140: =VLOOKUP(Tabela1[[#This Row],[PLACA]],UNIC!C:T,18,0) -> ATIVO | V140: =SUBSTITUTE(VLOOKUP(Tabela1[[#This Row],[PLACA]],UNIC!C:K,9,0),".", "") | W140: =VLOOKUP(Tabela1[[#This Row],[PLACA]],UNIC!C:M,10,0) -> 0 | X140: =VLOOKUP(Tabela1[[#This Row],[PLACA]],UNIC!C:M,11,0) -> 0 | Y140: =SUM(Tabela1[[#This Row],[GASTO COMBUSTÍVEL FEVEREIRO]:[GASTO COMBUSTÍVE ABRIL]]) -> 665.44 | Z140: =IFERROR(AVERAGE(Tabela1[[#This Row],[GASTO COMBUSTÍVE ABRIL]:[GASTO COMBUSTÍVE MARÇO]]),"-") -> 332.72
A141: EKL3749 | B141: =VLOOKUP(A141,UNIC!C:W,2,0) -> PUNTO | C141: =VLOOKUP(A141,UNIC!C:W,3,0) -> LEVE | D141: =VLOOKUP(A141,UNIC!C:W,5,0) -> 2009 | E141: =VLOOKUP(A141,UNIC!C:W,21,0) -> PARTICULAR | F141: =VLOOKUP(Tabela1[[#This Row],[PLACA]],UNIC!C:R,15,0) -> SP | G141: =VLOOKUP(Tabela1[[#This Row],[PLACA]],UNIC!C:R,16,0) -> SUDESTE | H141: =VLOOKUP(A141,UNIC!C:H,6,0) -> EMERSON PINHEIRO | I141: =VLOOKUP(H141,UNIC!H:J,3,0) -> COORDENADOR I | J141: =VLOOKUP(Tabela1[[#This Row],[PLACA]],UNIC!C:V,20,0) -> R$ 2.000,00 | K141: =IFERROR(VALUE(VLOOKUP(Tabela1[[#This Row],[PLACA]],[1]Planilha2!$A:$F,3,0)),"") -> 0 | L141: =IFERROR(VALUE(VLOOKUP(Tabela1[[#This Row],[PLACA]],[1]Planilha2!$A:$F,4,0)),"") -> 786.83 | M141: =IFERROR(VALUE(VLOOKUP(Tabela1[[#This Row],[PLACA]],[1]Planilha2!$A:$F,5,0)),"") -> 924.06 | O141: =VLOOKUP(Tabela1[[#This Row],[PLACA]],BASE_LOCADORAS!B:F,5,0) -> #N/A | P141: =IF(Tabela1[[#This Row],[VENCIMENTO CONTRATO]]="SEM DADOS", "SEM DADOS", IF(ISERROR(DATEDIF(TODAY(),Tabela1[[#This Row],[VENCIMENTO CONTRATO]],"d")), "VENCIDO", IF(DATEDIF(TODAY(),Tabela1[[#This Row],[VENCIMENTO CONTRATO]],"d")>90, "EM DIAS", "ATENÇÃO" ) ) ) -> #N/A | Q141: =VLOOKUP(Tabela1[[#This Row],[PLACA]],BASE_LOCADORAS!B:G,6,0) -> #N/A | R141: =Tabela1[[#This Row],[VALOR LOCADORA]]=Tabela1[[#This Row],[GASTO ALUGUEL]] -> #N/A | S141: =UPPER(TEXT(Tabela1[[#This Row],[VENCIMENTO CONTRATO]],"MMM")) -> #N/A | T141: =IFERROR(YEAR(Tabela1[[#This Row],[VENCIMENTO CONTRATO]]),"-") -> - | U141: =VLOOKUP(Tabela1[[#This Row],[PLACA]],UNIC!C:T,18,0) -> ATIVO | V141: =SUBSTITUTE(VLOOKUP(Tabela1[[#This Row],[PLACA]],UNIC!C:K,9,0),".", "") -> 99138 | W141: =VLOOKUP(Tabela1[[#This Row],[PLACA]],UNIC!C:M,10,0) -> 35001 | X141: =VLOOKUP(Tabela1[[#This Row],[PLACA]],UNIC!C:M,11,0) -> ADMINISTRATIVO | Y141: =SUM(Tabela1[[#This Row],[GASTO COMBUSTÍVEL FEVEREIRO]:[GASTO COMBUSTÍVE ABRIL]]) -> 1710.89 | Z141: =IFERROR(AVERAGE(Tabela1[[#This Row],[GASTO COMBUSTÍVE ABRIL]:[GASTO COMBUSTÍVE MARÇO]]),"-") -> 855.445
A142: OOA0977 | B142: =VLOOKUP(A142,UNIC!C:W,2,0) -> FIT | C142: =VLOOKUP(A142,UNIC!C:W,3,0) -> LEVE | D142: =VLOOKUP(A142,UNIC!C:W,5,0) -> 2023 | E142: =VLOOKUP(A142,UNIC!C:W,21,0) -> PARTICULAR | F142: =VLOOKUP(Tabela1[[#This Row],[PLACA]],UNIC!C:R,15,0) -> GO | G142: =VLOOKUP(Tabela1[[#This Row],[PLACA]],UNIC!C:R,16,0) -> CENTRO OESTE | H142: =VLOOKUP(A142,UNIC!C:H,6,0) -> LESLYE HUMBERTO PEREIRA RAMOS | I142: =VLOOKUP(H142,UNIC!H:J,3,0) -> ASSISTENTE DE FROTA | J142: =VLOOKUP(Tabela1[[#This Row],[PLACA]],UNIC!C:V,20,0) -> R$ 1.550,00 | K142: =IFERROR(VALUE(VLOOKUP(Tabela1[[#This Row],[PLACA]],[1]Planilha2!$A:$F,3,0)),"") -> 0 | L142: =IFERROR(VALUE(VLOOKUP(Tabela1[[#This Row],[PLACA]],[1]Planilha2!$A:$F,4,0)),"") -> 90.09 | M142: =IFERROR(VALUE(VLOOKUP(Tabela1[[#This Row],[PLACA]],[1]Planilha2!$A:$F,5,0)),"") -> 0 | O142: =VLOOKUP(Tabela1[[#This Row],[PLACA]],BASE_LOCADORAS!B:F,5,0) -> #N/A | P142: =IF(Tabela1[[#This Row],[VENCIMENTO CONTRATO]]="SEM DADOS", "SEM DADOS", IF(ISERROR(DATEDIF(TODAY(),Tabela1[[#This Row],[VENCIMENTO CONTRATO]],"d")), "VENCIDO", IF(DATEDIF(TODAY(),Tabela1[[#This Row],[VENCIMENTO CONTRATO]],"d")>90, "EM DIAS", "ATENÇÃO" ) ) ) -> #N/A | Q142: =VLOOKUP(Tabela1[[#This Row],[PLACA]],BASE_LOCADORAS!B:G,6,0) -> #N/A | R142: =Tabela1[[#This Row],[VALOR LOCADORA]]=Tabela1[[#This Row],[GASTO ALUGUEL]] -> #N/A | S142: =UPPER(TEXT(Tabela1[[#This Row],[VENCIMENTO CONTRATO]],"MMM")) -> #N/A | T142: =IFERROR(YEAR(Tabela1[[#This Row],[VENCIMENTO CONTRATO]]),"-") -> - | U142: =VLOOKUP(Tabela1[[#This Row],[PLACA]],UNIC!C:T,18,0) -> ATIVO | V142: =SUBSTITUTE(VLOOKUP(Tabela1[[#This Row],[PLACA]],UNIC!C:K,9,0),".", "") -> 99628 | W142: =VLOOKUP(Tabela1[[#This Row],[PLACA]],UNIC!C:M,10,0) -> 19019 | X142: =VLOOKUP(Tabela1[[#This Row],[PLACA]],UNIC!C:M,11,0) -> ADMINISTRATIVO | Y142: =SUM(Tabela1[[#This Row],[GASTO COMBUSTÍVEL FEVEREIRO]:[GASTO COMBUSTÍVE ABRIL]]) -> 90.09 | Z142: =IFERROR(AVERAGE(Tabela1[[#This Row],[GASTO COMBUSTÍVE ABRIL]:[GASTO COMBUSTÍVE MARÇO]]),"-") -> 45.045
A143: GER2781 | B143: =VLOOKUP(A143,UNIC!C:W,2,0) -> B4T 9000E | C143: =VLOOKUP(A143,UNIC!C:W,3,0) -> GERADOR | D143: =VLOOKUP(A143,UNIC!C:W,5,0) -> 2026 | E143: =VLOOKUP(A143,UNIC!C:W,21,0) -> EQUIPAMENTO | F143: =VLOOKUP(Tabela1[[#This Row],[PLACA]],UNIC!C:R,15,0) -> TO | G143: =VLOOKUP(Tabela1[[#This Row],[PLACA]],UNIC!C:R,16,0) -> NORTE | H143: =VLOOKUP(A143,UNIC!C:H,6,0) -> - | I143: =VLOOKUP(H143,UNIC!H:J,3,0) -> - | J143: =VLOOKUP(Tabela1[[#This Row],[PLACA]],UNIC!C:V,20,0) -> R$ 0,01 | K143: =IFERROR(VALUE(VLOOKUP(Tabela1[[#This Row],[PLACA]],[1]Planilha2!$A:$F,3,0)),"") -> 0 | L143: =IFERROR(VALUE(VLOOKUP(Tabela1[[#This Row],[PLACA]],[1]Planilha2!$A:$F,4,0)),"") -> 1669.79 | M143: =IFERROR(VALUE(VLOOKUP(Tabela1[[#This Row],[PLACA]],[1]Planilha2!$A:$F,5,0)),"") -> 432.13 | O143: =VLOOKUP(Tabela1[[#This Row],[PLACA]],BASE_LOCADORAS!B:F,5,0) -> #N/A | P143: =IF(Tabela1[[#This Row],[VENCIMENTO CONTRATO]]="SEM DADOS", "SEM DADOS", IF(ISERROR(DATEDIF(TODAY(),Tabela1[[#This Row],[VENCIMENTO CONTRATO]],"d")), "VENCIDO", IF(DATEDIF(TODAY(),Tabela1[[#This Row],[VENCIMENTO CONTRATO]],"d")>90, "EM DIAS", "ATENÇÃO" ) ) ) -> #N/A | Q143: =VLOOKUP(Tabela1[[#This Row],[PLACA]],BASE_LOCADORAS!B:G,6,0) -> #N/A | R143: =Tabela1[[#This Row],[VALOR LOCADORA]]=Tabela1[[#This Row],[GASTO ALUGUEL]] -> #N/A | S143: =UPPER(TEXT(Tabela1[[#This Row],[VENCIMENTO CONTRATO]],"MMM")) -> #N/A | T143: =IFERROR(YEAR(Tabela1[[#This Row],[VENCIMENTO CONTRATO]]),"-") -> - | U143: =VLOOKUP(Tabela1[[#This Row],[PLACA]],UNIC!C:T,18,0) -> ATIVO | V143: =SUBSTITUTE(VLOOKUP(Tabela1[[#This Row],[PLACA]],UNIC!C:K,9,0),".", "") | W143: =VLOOKUP(Tabela1[[#This Row],[PLACA]],UNIC!C:M,10,0) -> 0 | X143: =VLOOKUP(Tabela1[[#This Row],[PLACA]],UNIC!C:M,11,0) -> 0 | Y143: =SUM(Tabela1[[#This Row],[GASTO COMBUSTÍVEL FEVEREIRO]:[GASTO COMBUSTÍVE ABRIL]]) -> 2101.92 | Z143: =IFERROR(AVERAGE(Tabela1[[#This Row],[GASTO COMBUSTÍVE ABRIL]:[GASTO COMBUSTÍVE MARÇO]]),"-") -> 1050.96
A144: GER2785 | B144: =VLOOKUP(A144,UNIC!C:W,2,0) -> B4T 9000E | C144: =VLOOKUP(A144,UNIC!C:W,3,0) -> GERADOR | D144: =VLOOKUP(A144,UNIC!C:W,5,0) -> 2026 | E144: =VLOOKUP(A144,UNIC!C:W,21,0) -> EQUIPAMENTO | F144: =VLOOKUP(Tabela1[[#This Row],[PLACA]],UNIC!C:R,15,0) -> TO | G144: =VLOOKUP(Tabela1[[#This Row],[PLACA]],UNIC!C:R,16,0) -> NORTE | H144: =VLOOKUP(A144,UNIC!C:H,6,0) -> - | I144: =VLOOKUP(H144,UNIC!H:J,3,0) -> - | J144: =VLOOKUP(Tabela1[[#This Row],[PLACA]],UNIC!C:V,20,0) -> R$ 0,01 | K144: =IFERROR(VALUE(VLOOKUP(Tabela1[[#This Row],[PLACA]],[1]Planilha2!$A:$F,3,0)),"") -> 0 | L144: =IFERROR(VALUE(VLOOKUP(Tabela1[[#This Row],[PLACA]],[1]Planilha2!$A:$F,4,0)),"") -> 1639.53 | M144: =IFERROR(VALUE(VLOOKUP(Tabela1[[#This Row],[PLACA]],[1]Planilha2!$A:$F,5,0)),"") -> 0 | O144: =VLOOKUP(Tabela1[[#This Row],[PLACA]],BASE_LOCADORAS!B:F,5,0) -> #N/A | P144: =IF(Tabela1[[#This Row],[VENCIMENTO CONTRATO]]="SEM DADOS", "SEM DADOS", IF(ISERROR(DATEDIF(TODAY(),Tabela1[[#This Row],[VENCIMENTO CONTRATO]],"d")), "VENCIDO", IF(DATEDIF(TODAY(),Tabela1[[#This Row],[VENCIMENTO CONTRATO]],"d")>90, "EM DIAS", "ATENÇÃO" ) ) ) -> #N/A | Q144: =VLOOKUP(Tabela1[[#This Row],[PLACA]],BASE_LOCADORAS!B:G,6,0) -> #N/A | R144: =Tabela1[[#This Row],[VALOR LOCADORA]]=Tabela1[[#This Row],[GASTO ALUGUEL]] -> #N/A | S144: =UPPER(TEXT(Tabela1[[#This Row],[VENCIMENTO CONTRATO]],"MMM")) -> #N/A | T144: =IFERROR(YEAR(Tabela1[[#This Row],[VENCIMENTO CONTRATO]]),"-") -> - | U144: =VLOOKUP(Tabela1[[#This Row],[PLACA]],UNIC!C:T,18,0) -> ATIVO | V144: =SUBSTITUTE(VLOOKUP(Tabela1[[#This Row],[PLACA]],UNIC!C:K,9,0),".", "") | W144: =VLOOKUP(Tabela1[[#This Row],[PLACA]],UNIC!C:M,10,0) -> 0 | X144: =VLOOKUP(Tabela1[[#This Row],[PLACA]],UNIC!C:M,11,0) -> 0 | Y144: =SUM(Tabela1[[#This Row],[GASTO COMBUSTÍVEL FEVEREIRO]:[GASTO COMBUSTÍVE ABRIL]]) -> 1639.53 | Z144: =IFERROR(AVERAGE(Tabela1[[#This Row],[GASTO COMBUSTÍVE ABRIL]:[GASTO COMBUSTÍVE MARÇO]]),"-") -> 819.765
A145: GER2787 | B145: =VLOOKUP(A145,UNIC!C:W,2,0) -> B4T 9000E | C145: =VLOOKUP(A145,UNIC!C:W,3,0) -> GERADOR | D145: =VLOOKUP(A145,UNIC!C:W,5,0) -> 2026 | E145: =VLOOKUP(A145,UNIC!C:W,21,0) -> EQUIPAMENTO | F145: =VLOOKUP(Tabela1[[#This Row],[PLACA]],UNIC!C:R,15,0) -> TO | G145: =VLOOKUP(Tabela1[[#This Row],[PLACA]],UNIC!C:R,16,0) -> NORTE | H145: =VLOOKUP(A145,UNIC!C:H,6,0) -> - | I145: =VLOOKUP(H145,UNIC!H:J,3,0) -> - | J145: =VLOOKUP(Tabela1[[#This Row],[PLACA]],UNIC!C:V,20,0) -> R$ 0,01 | K145: =IFERROR(VALUE(VLOOKUP(Tabela1[[#This Row],[PLACA]],[1]Planilha2!$A:$F,3,0)),"") -> 0 | L145: =IFERROR(VALUE(VLOOKUP(Tabela1[[#This Row],[PLACA]],[1]Planilha2!$A:$F,4,0)),"") -> 913.97 | M145: =IFERROR(VALUE(VLOOKUP(Tabela1[[#This Row],[PLACA]],[1]Planilha2!$A:$F,5,0)),"") -> 1602.1 | O145: =VLOOKUP(Tabela1[[#This Row],[PLACA]],BASE_LOCADORAS!B:F,5,0) -> #N/A | P145: =IF(Tabela1[[#This Row],[VENCIMENTO CONTRATO]]="SEM DADOS", "SEM DADOS", IF(ISERROR(DATEDIF(TODAY(),Tabela1[[#This Row],[VENCIMENTO CONTRATO]],"d")), "VENCIDO", IF(DATEDIF(TODAY(),Tabela1[[#This Row],[VENCIMENTO CONTRATO]],"d")>90, "EM DIAS", "ATENÇÃO" ) ) ) -> #N/A | Q145: =VLOOKUP(Tabela1[[#This Row],[PLACA]],BASE_LOCADORAS!B:G,6,0) -> #N/A | R145: =Tabela1[[#This Row],[VALOR LOCADORA]]=Tabela1[[#This Row],[GASTO ALUGUEL]] -> #N/A | S145: =UPPER(TEXT(Tabela1[[#This Row],[VENCIMENTO CONTRATO]],"MMM")) -> #N/A | T145: =IFERROR(YEAR(Tabela1[[#This Row],[VENCIMENTO CONTRATO]]),"-") -> - | U145: =VLOOKUP(Tabela1[[#This Row],[PLACA]],UNIC!C:T,18,0) -> ATIVO | V145: =SUBSTITUTE(VLOOKUP(Tabela1[[#This Row],[PLACA]],UNIC!C:K,9,0),".", "") | W145: =VLOOKUP(Tabela1[[#This Row],[PLACA]],UNIC!C:M,10,0) -> 0 | X145: =VLOOKUP(Tabela1[[#This Row],[PLACA]],UNIC!C:M,11,0) -> 0 | Y145: =SUM(Tabela1[[#This Row],[GASTO COMBUSTÍVEL FEVEREIRO]:[GASTO COMBUSTÍVE ABRIL]]) -> 2516.07 | Z145: =IFERROR(AVERAGE(Tabela1[[#This Row],[GASTO COMBUSTÍVE ABRIL]:[GASTO COMBUSTÍVE MARÇO]]),"-") -> 1258.035
A146: JWR8D42 | B146: =VLOOKUP(A146,UNIC!C:W,2,0) -> CELTA | C146: =VLOOKUP(A146,UNIC!C:W,3,0) -> LEVE | D146: =VLOOKUP(A146,UNIC!C:W,5,0) -> 2012 | E146: =VLOOKUP(A146,UNIC!C:W,21,0) -> PARTICULAR | F146: =VLOOKUP(Tabela1[[#This Row],[PLACA]],UNIC!C:R,15,0) -> AM | G146: =VLOOKUP(Tabela1[[#This Row],[PLACA]],UNIC!C:R,16,0) -> NORTE | H146: =VLOOKUP(A146,UNIC!C:H,6,0) -> - | I146: =VLOOKUP(H146,UNIC!H:J,3,0) -> - | J146: =VLOOKUP(Tabela1[[#This Row],[PLACA]],UNIC!C:V,20,0) -> R$ 0,00 | K146: =IFERROR(VALUE(VLOOKUP(Tabela1[[#This Row],[PLACA]],[1]Planilha2!$A:$F,3,0)),"") -> 0 | L146: =IFERROR(VALUE(VLOOKUP(Tabela1[[#This Row],[PLACA]],[1]Planilha2!$A:$F,4,0)),"") -> 257.7 | M146: =IFERROR(VALUE(VLOOKUP(Tabela1[[#This Row],[PLACA]],[1]Planilha2!$A:$F,5,0)),"") -> 0 | O146: =VLOOKUP(Tabela1[[#This Row],[PLACA]],BASE_LOCADORAS!B:F,5,0) -> #N/A | P146: =IF(Tabela1[[#This Row],[VENCIMENTO CONTRATO]]="SEM DADOS", "SEM DADOS", IF(ISERROR(DATEDIF(TODAY(),Tabela1[[#This Row],[VENCIMENTO CONTRATO]],"d")), "VENCIDO", IF(DATEDIF(TODAY(),Tabela1[[#This Row],[VENCIMENTO CONTRATO]],"d")>90, "EM DIAS", "ATENÇÃO" ) ) ) -> #N/A | Q146: =VLOOKUP(Tabela1[[#This Row],[PLACA]],BASE_LOCADORAS!B:G,6,0) -> #N/A | R146: =Tabela1[[#This Row],[VALOR LOCADORA]]=Tabela1[[#This Row],[GASTO ALUGUEL]] -> #N/A | S146: =UPPER(TEXT(Tabela1[[#This Row],[VENCIMENTO CONTRATO]],"MMM")) -> #N/A | T146: =IFERROR(YEAR(Tabela1[[#This Row],[VENCIMENTO CONTRATO]]),"-") -> - | U146: =VLOOKUP(Tabela1[[#This Row],[PLACA]],UNIC!C:T,18,0) -> PATIO | V146: =SUBSTITUTE(VLOOKUP(Tabela1[[#This Row],[PLACA]],UNIC!C:K,9,0),".", "") | W146: =VLOOKUP(Tabela1[[#This Row],[PLACA]],UNIC!C:M,10,0) -> 0 | X146: =VLOOKUP(Tabela1[[#This Row],[PLACA]],UNIC!C:M,11,0) -> 0 | Y146: =SUM(Tabela1[[#This Row],[GASTO COMBUSTÍVEL FEVEREIRO]:[GASTO COMBUSTÍVE ABRIL]]) -> 257.7 | Z146: =IFERROR(AVERAGE(Tabela1[[#This Row],[GASTO COMBUSTÍVE ABRIL]:[GASTO COMBUSTÍVE MARÇO]]),"-") -> 128.85
A147: QUL9I64 | B147: =VLOOKUP(A147,UNIC!C:W,2,0) -> KA | C147: =VLOOKUP(A147,UNIC!C:W,3,0) -> LEVE | D147: =VLOOKUP(A147,UNIC!C:W,5,0) -> 2012 | E147: =VLOOKUP(A147,UNIC!C:W,21,0) -> PARTICULAR | F147: =VLOOKUP(Tabela1[[#This Row],[PLACA]],UNIC!C:R,15,0) -> AM | G147: =VLOOKUP(Tabela1[[#This Row],[PLACA]],UNIC!C:R,16,0) -> NORTE | H147: =VLOOKUP(A147,UNIC!C:H,6,0) -> - | I147: =VLOOKUP(H147,UNIC!H:J,3,0) -> - | J147: =VLOOKUP(Tabela1[[#This Row],[PLACA]],UNIC!C:V,20,0) -> R$ 0,00 | K147: =IFERROR(VALUE(VLOOKUP(Tabela1[[#This Row],[PLACA]],[1]Planilha2!$A:$F,3,0)),"") -> 0 | L147: =IFERROR(VALUE(VLOOKUP(Tabela1[[#This Row],[PLACA]],[1]Planilha2!$A:$F,4,0)),"") -> 459.98 | M147: =IFERROR(VALUE(VLOOKUP(Tabela1[[#This Row],[PLACA]],[1]Planilha2!$A:$F,5,0)),"") -> 459.98 | O147: =VLOOKUP(Tabela1[[#This Row],[PLACA]],BASE_LOCADORAS!B:F,5,0) -> #N/A | P147: =IF(Tabela1[[#This Row],[VENCIMENTO CONTRATO]]="SEM DADOS", "SEM DADOS", IF(ISERROR(DATEDIF(TODAY(),Tabela1[[#This Row],[VENCIMENTO CONTRATO]],"d")), "VENCIDO", IF(DATEDIF(TODAY(),Tabela1[[#This Row],[VENCIMENTO CONTRATO]],"d")>90, "EM DIAS", "ATENÇÃO" ) ) ) -> #N/A | Q147: =VLOOKUP(Tabela1[[#This Row],[PLACA]],BASE_LOCADORAS!B:G,6,0) -> #N/A | R147: =Tabela1[[#This Row],[VALOR LOCADORA]]=Tabela1[[#This Row],[GASTO ALUGUEL]] -> #N/A | S147: =UPPER(TEXT(Tabela1[[#This Row],[VENCIMENTO CONTRATO]],"MMM")) -> #N/A | T147: =IFERROR(YEAR(Tabela1[[#This Row],[VENCIMENTO CONTRATO]]),"-") -> - | U147: =VLOOKUP(Tabela1[[#This Row],[PLACA]],UNIC!C:T,18,0) -> ATIVO | V147: =SUBSTITUTE(VLOOKUP(Tabela1[[#This Row],[PLACA]],UNIC!C:K,9,0),".", "") | W147: =VLOOKUP(Tabela1[[#This Row],[PLACA]],UNIC!C:M,10,0) -> 0 | X147: =VLOOKUP(Tabela1[[#This Row],[PLACA]],UNIC!C:M,11,0) -> 0 | Y147: =SUM(Tabela1[[#This Row],[GASTO COMBUSTÍVEL FEVEREIRO]:[GASTO COMBUSTÍVE ABRIL]]) -> 919.96 | Z147: =IFERROR(AVERAGE(Tabela1[[#This Row],[GASTO COMBUSTÍVE ABRIL]:[GASTO COMBUSTÍVE MARÇO]]),"-") -> 459.98
A148: PHH2066 | B148: =VLOOKUP(A148,UNIC!C:W,2,0) -> GOL | C148: =VLOOKUP(A148,UNIC!C:W,3,0) -> LEVE | D148: =VLOOKUP(A148,UNIC!C:W,5,0) -> 2012 | E148: =VLOOKUP(A148,UNIC!C:W,21,0) -> PARTICULAR | F148: =VLOOKUP(Tabela1[[#This Row],[PLACA]],UNIC!C:R,15,0) -> AM | G148: =VLOOKUP(Tabela1[[#This Row],[PLACA]],UNIC!C:R,16,0) -> NORTE | H148: =VLOOKUP(A148,UNIC!C:H,6,0) -> - | I148: =VLOOKUP(H148,UNIC!H:J,3,0) -> - | J148: =VLOOKUP(Tabela1[[#This Row],[PLACA]],UNIC!C:V,20,0) -> R$ 0,00 | K148: =IFERROR(VALUE(VLOOKUP(Tabela1[[#This Row],[PLACA]],[1]Planilha2!$A:$F,3,0)),"") -> 0 | L148: =IFERROR(VALUE(VLOOKUP(Tabela1[[#This Row],[PLACA]],[1]Planilha2!$A:$F,4,0)),"") -> 230 | M148: =IFERROR(VALUE(VLOOKUP(Tabela1[[#This Row],[PLACA]],[1]Planilha2!$A:$F,5,0)),"") -> 0 | O148: =VLOOKUP(Tabela1[[#This Row],[PLACA]],BASE_LOCADORAS!B:F,5,0) -> #N/A | P148: =IF(Tabela1[[#This Row],[VENCIMENTO CONTRATO]]="SEM DADOS", "SEM DADOS", IF(ISERROR(DATEDIF(TODAY(),Tabela1[[#This Row],[VENCIMENTO CONTRATO]],"d")), "VENCIDO", IF(DATEDIF(TODAY(),Tabela1[[#This Row],[VENCIMENTO CONTRATO]],"d")>90, "EM DIAS", "ATENÇÃO" ) ) ) -> #N/A | Q148: =VLOOKUP(Tabela1[[#This Row],[PLACA]],BASE_LOCADORAS!B:G,6,0) -> #N/A | R148: =Tabela1[[#This Row],[VALOR LOCADORA]]=Tabela1[[#This Row],[GASTO ALUGUEL]] -> #N/A | S148: =UPPER(TEXT(Tabela1[[#This Row],[VENCIMENTO CONTRATO]],"MMM")) -> #N/A | T148: =IFERROR(YEAR(Tabela1[[#This Row],[VENCIMENTO CONTRATO]]),"-") -> - | U148: =VLOOKUP(Tabela1[[#This Row],[PLACA]],UNIC!C:T,18,0) -> ATIVO | V148: =SUBSTITUTE(VLOOKUP(Tabela1[[#This Row],[PLACA]],UNIC!C:K,9,0),".", "") | W148: =VLOOKUP(Tabela1[[#This Row],[PLACA]],UNIC!C:M,10,0) -> 0 | X148: =VLOOKUP(Tabela1[[#This Row],[PLACA]],UNIC!C:M,11,0) -> 0 | Y148: =SUM(Tabela1[[#This Row],[GASTO COMBUSTÍVEL FEVEREIRO]:[GASTO COMBUSTÍVE ABRIL]]) -> 230 | Z148: =IFERROR(AVERAGE(Tabela1[[#This Row],[GASTO COMBUSTÍVE ABRIL]:[GASTO COMBUSTÍVE MARÇO]]),"-") -> 115
A149: OAK6I24 | B149: =VLOOKUP(A149,UNIC!C:W,2,0) -> SAVEIRO | C149: =VLOOKUP(A149,UNIC!C:W,3,0) -> UTILITARIO | D149: =VLOOKUP(A149,UNIC!C:W,5,0) -> 2012 | E149: =VLOOKUP(A149,UNIC!C:W,21,0) -> PARTICULAR | F149: =VLOOKUP(Tabela1[[#This Row],[PLACA]],UNIC!C:R,15,0) -> AM | G149: =VLOOKUP(Tabela1[[#This Row],[PLACA]],UNIC!C:R,16,0) -> NORTE | H149: =VLOOKUP(A149,UNIC!C:H,6,0) -> - | I149: =VLOOKUP(H149,UNIC!H:J,3,0) -> - | J149: =VLOOKUP(Tabela1[[#This Row],[PLACA]],UNIC!C:V,20,0) -> R$ 0,00 | K149: =IFERROR(VALUE(VLOOKUP(Tabela1[[#This Row],[PLACA]],[1]Planilha2!$A:$F,3,0)),"") | L149: =IFERROR(VALUE(VLOOKUP(Tabela1[[#This Row],[PLACA]],[1]Planilha2!$A:$F,4,0)),"") | M149: =IFERROR(VALUE(VLOOKUP(Tabela1[[#This Row],[PLACA]],[1]Planilha2!$A:$F,5,0)),"") | O149: =VLOOKUP(Tabela1[[#This Row],[PLACA]],BASE_LOCADORAS!B:F,5,0) -> #N/A | P149: =IF(Tabela1[[#This Row],[VENCIMENTO CONTRATO]]="SEM DADOS", "SEM DADOS", IF(ISERROR(DATEDIF(TODAY(),Tabela1[[#This Row],[VENCIMENTO CONTRATO]],"d")), "VENCIDO", IF(DATEDIF(TODAY(),Tabela1[[#This Row],[VENCIMENTO CONTRATO]],"d")>90, "EM DIAS", "ATENÇÃO" ) ) ) -> #N/A | Q149: =VLOOKUP(Tabela1[[#This Row],[PLACA]],BASE_LOCADORAS!B:G,6,0) -> #N/A | R149: =Tabela1[[#This Row],[VALOR LOCADORA]]=Tabela1[[#This Row],[GASTO ALUGUEL]] -> #N/A | S149: =UPPER(TEXT(Tabela1[[#This Row],[VENCIMENTO CONTRATO]],"MMM")) -> #N/A | T149: =IFERROR(YEAR(Tabela1[[#This Row],[VENCIMENTO CONTRATO]]),"-") -> - | U149: =VLOOKUP(Tabela1[[#This Row],[PLACA]],UNIC!C:T,18,0) -> ATIVO | V149: =SUBSTITUTE(VLOOKUP(Tabela1[[#This Row],[PLACA]],UNIC!C:K,9,0),".", "") | W149: =VLOOKUP(Tabela1[[#This Row],[PLACA]],UNIC!C:M,10,0) -> 0 | X149: =VLOOKUP(Tabela1[[#This Row],[PLACA]],UNIC!C:M,11,0) -> 0 | Y149: =SUM(Tabela1[[#This Row],[GASTO COMBUSTÍVEL FEVEREIRO]:[GASTO COMBUSTÍVE ABRIL]]) -> 0 | Z149: =IFERROR(AVERAGE(Tabela1[[#This Row],[GASTO COMBUSTÍVE ABRIL]:[GASTO COMBUSTÍVE MARÇO]]),"-") -> -
A150: OAJ3I23 | B150: =VLOOKUP(A150,UNIC!C:W,2,0) -> FOX | C150: =VLOOKUP(A150,UNIC!C:W,3,0) -> LEVE | D150: =VLOOKUP(A150,UNIC!C:W,5,0) -> 2012 | E150: =VLOOKUP(A150,UNIC!C:W,21,0) -> PARTICULAR | F150: =VLOOKUP(Tabela1[[#This Row],[PLACA]],UNIC!C:R,15,0) -> AM | G150: =VLOOKUP(Tabela1[[#This Row],[PLACA]],UNIC!C:R,16,0) -> NORTE | H150: =VLOOKUP(A150,UNIC!C:H,6,0) -> - | I150: =VLOOKUP(H150,UNIC!H:J,3,0) -> - | J150: =VLOOKUP(Tabela1[[#This Row],[PLACA]],UNIC!C:V,20,0) -> R$ 0,00 | K150: =IFERROR(VALUE(VLOOKUP(Tabela1[[#This Row],[PLACA]],[1]Planilha2!$A:$F,3,0)),"") | L150: =IFERROR(VALUE(VLOOKUP(Tabela1[[#This Row],[PLACA]],[1]Planilha2!$A:$F,4,0)),"") | M150: =IFERROR(VALUE(VLOOKUP(Tabela1[[#This Row],[PLACA]],[1]Planilha2!$A:$F,5,0)),"") | O150: =VLOOKUP(Tabela1[[#This Row],[PLACA]],BASE_LOCADORAS!B:F,5,0) -> #N/A | P150: =IF(Tabela1[[#This Row],[VENCIMENTO CONTRATO]]="SEM DADOS", "SEM DADOS", IF(ISERROR(DATEDIF(TODAY(),Tabela1[[#This Row],[VENCIMENTO CONTRATO]],"d")), "VENCIDO", IF(DATEDIF(TODAY(),Tabela1[[#This Row],[VENCIMENTO CONTRATO]],"d")>90, "EM DIAS", "ATENÇÃO" ) ) ) -> #N/A | Q150: =VLOOKUP(Tabela1[[#This Row],[PLACA]],BASE_LOCADORAS!B:G,6,0) -> #N/A | R150: =Tabela1[[#This Row],[VALOR LOCADORA]]=Tabela1[[#This Row],[GASTO ALUGUEL]] -> #N/A | S150: =UPPER(TEXT(Tabela1[[#This Row],[VENCIMENTO CONTRATO]],"MMM")) -> #N/A | T150: =IFERROR(YEAR(Tabela1[[#This Row],[VENCIMENTO CONTRATO]]),"-") -> - | U150: =VLOOKUP(Tabela1[[#This Row],[PLACA]],UNIC!C:T,18,0) -> ATIVO | V150: =SUBSTITUTE(VLOOKUP(Tabela1[[#This Row],[PLACA]],UNIC!C:K,9,0),".", "") | W150: =VLOOKUP(Tabela1[[#This Row],[PLACA]],UNIC!C:M,10,0) -> 0 | X150: =VLOOKUP(Tabela1[[#This Row],[PLACA]],UNIC!C:M,11,0) -> 0 | Y150: =SUM(Tabela1[[#This Row],[GASTO COMBUSTÍVEL FEVEREIRO]:[GASTO COMBUSTÍVE ABRIL]]) -> 0 | Z150: =IFERROR(AVERAGE(Tabela1[[#This Row],[GASTO COMBUSTÍVE ABRIL]:[GASTO COMBUSTÍVE MARÇO]]),"-") -> -
